<mujoco model="cyber_dog">
  <compiler angle="radian" meshdir="meshes/"/>

  <default>
    <default class="cyberdog">
      <geom friction="0.4" margin="0.001" condim="1"/>
      <joint axis="0 1 0" damping="0.01" armature="0.01" frictionloss="0.1"/>
      <motor ctrlrange="-12.0001 12.0001"/>
      <default class="abduction">
        <joint axis="1 0 0" range="-0.68 0.68"/>
      </default>
      <default class="hip">
        <default class="front_hip">
          <joint range="-1.3258 2.7911"/>
        </default>
        <default class="back_hip">
          <joint range="-0.9769 3.1416"/>
        </default>
      </default>
      <default class="knee">
        <joint range="-2.53073 -0.523599"/>
      </default>
      <default class="visual">
        <geom type="mesh" contype="0" conaffinity="0" group="2" material="dark"/>
      </default>
      <default class="collision">
        <geom group="3"/>
        <default class="foot">
          <geom size="0.022" pos="-0.002 0 -0.213" priority="1" condim="6"
                friction="0.4 0.02 0.01"/>
        </default>
      </default>
    </default>
  </default>

  <asset>
    <material name="metal" rgba=".5 .5 .5 1" shininess="0.25" specular="0"/>
    <material name="black" rgba=".1 .1 .1 1" shininess="0.25"/>
    <material name="dark" rgba="0.2 0.2 0.2 1" shininess="0.1"/>
    <material name="transparent" rgba="1 1 1 0.01"/>

    <mesh name="body" file="body.stl"/>
    <mesh name="hip" file="hip.stl"/>
    <mesh name="hip_mirror" file="hip_mirror.stl"/>
    <mesh name="abad" file="abad.stl"/>
    <mesh name="knee" file="knee.stl"/>
  </asset>

  <worldbody>
    <body name="base_link" pos="0 0 0.31" childclass="cyberdog">

      <inertial pos="0.0273 -0.000242 0.0143" quat="0 0 0 1"
                mass="4.03"
                diaginertia="0.0185 0.0517 0.0483"/>
      <freejoint/>
      <geom size="0.118 0.095 0.0545" type="box" class="collision"/>

      <geom type="mesh" class="visual" material="black" mesh="body"/>

      <geom size="0.0005 0.0005 0.0005" pos="0.0334 -0.0172765 0.0510469" type="box"/>
      <geom size="0.0005 0.0005 0.0005" pos="0.271994 0.025 0.114912" type="box"/>
      <geom size="0.0005 0.0005 0.0005" pos="0.27576 0 0.125794" type="box"/>
      <geom size="0.0005 0.0005 0.0005" pos="0.290228 0 0.14742" type="box"/>
      <geom size="0.038 0.03 0.02" pos="0.256 0 0.12" type="box" class="collision"/>
      <geom size="0.01 0.04 0.05" pos="0.225 0 0.15" type="box" class="collision"/>
      <site name="imu" pos="0 0 0"/>

      <body name="FL_abad" pos="0.164 0.042 0">
        <inertial pos="-0.00870249 0.0262609 -0.00018743" quat="-0.216425 0.671536 0.22334 0.672547" mass="0.577943"
                  diaginertia="0.000797811 0.000747905 0.000457908"/>
        <joint name="FL_hip_joint" class="abduction"/>
        <geom size="0.039 0.0175" quat="0.707107 0.707107 0 0" type="cylinder" class="collision"/>
        <geom size="0.039 0.0175" pos="0 0.059 0" quat="0.707107 0.707107 0 0" type="cylinder" class="collision"/>
        <geom type="mesh" class="visual" material="dark" mesh="abad"/>
        <body name="FL_hip" pos="0 0.094 0">
          <inertial pos="-0.00171622 -0.0276376 -0.0148955" quat="0.972561 0.187345 0.00546887 0.137833" mass="0.5954"
                    diaginertia="0.00125179 0.00120656 0.000449032"/>
          <joint name="FL_thigh_joint" class="front_hip"/>
          <geom size="0.06 0.0125 0.017" pos="0 0 -0.06" quat="0.707107 0 0.707107 0" type="box" class="collision"/>
          <geom type="mesh" class="visual" material="dark" mesh="hip"/>
          <body name="FL_knee" pos="0 0 -0.12">
            <inertial pos="0.00157271 -3.78302e-05 -0.106096" quat="0.708712 -0.0140225 -0.0146892 0.705206"
                      mass="0.144731" diaginertia="0.000843553 0.00083835 1.87502e-05"/>
            <joint name="FL_calf_joint" class="knee"/>
            <geom class="visual" material="metal" type="mesh" mesh="knee"/>
            <geom size="0.008 0.008 0.091705" pos="0 0 -0.091705" quat="0 0 1 0" type="box" class="collision"/>
            <geom name="FL_knee_rubber" size="0.016" pos="-0.01 0 -0.007" quat="0 0 1 0" class="collision"/>
            <geom size="0.019" pos="0.0055 0 -0.17391" class="collision"/>
            <site name="FL_touch" pos="0.0055 0 -0.17391" size="0.02" material="transparent"/>
          </body>
        </body>
      </body>
      <body name="FR_abad" pos="0.164 -0.042 0">
        <inertial pos="-0.00870249 -0.0262609 -0.00018743" quat="0.216425 0.671536 -0.22334 0.672547" mass="0.577943"
                  diaginertia="0.000797811 0.000747905 0.000457908"/>
        <joint name="FR_hip_joint" class="abduction"/>
        <geom size="0.039 0.0175" quat="0.707107 0.707107 0 0" type="cylinder" class="collision"/>
        <geom size="0.039 0.0175" pos="0 -0.059 0" quat="0.707107 0.707107 0 0" type="cylinder" class="collision"/>
        <geom quat="0 1 0 0" type="mesh" class="visual" material="dark" mesh="abad"/>
        <body name="FR_hip" pos="0 -0.094 0">
          <inertial pos="-0.00171622 0.0276376 -0.0148955" quat="0.972561 -0.187345 0.00546887 -0.137833" mass="0.5954"
                    diaginertia="0.00125179 0.00120656 0.000449032"/>
          <joint name="FR_thigh_joint" class="front_hip"/>
          <geom size="0.06 0.0125 0.017" pos="0 0 -0.06" quat="0.707107 0 0.707107 0" type="box" class="collision"/>
          <geom type="mesh" class="visual" material="dark" mesh="hip_mirror"/>
          <body name="FR_knee" pos="0 0 -0.12">
            <inertial pos="0.00157271 -3.78302e-05 -0.106096" quat="0.708712 -0.0140225 -0.0146892 0.705206"
                      mass="0.144731" diaginertia="0.000843553 0.00083835 1.87502e-05"/>
            <joint name="FR_calf_joint" class="knee"/>
            <geom class="visual" material="metal" type="mesh" mesh="knee"/>
            <geom size="0.008 0.008 0.091705" pos="0 0 -0.091705" quat="0 0 1 0" type="box" class="collision"/>
            <geom name="FR_knee_rubber" size="0.016" pos="-0.01 0 -0.007" quat="0 0 1 0" class="collision"/>
            <geom size="0.019" pos="0.0055 0 -0.17391" class="collision"/>
            <site name="FR_touch" pos="0.0055 0 -0.17391" size="0.019" material="transparent"/>
          </body>
        </body>
      </body>
      <body name="RL_abad" pos="-0.164 0.042 0">
        <inertial pos="0.00870249 0.0262609 -0.00018743" quat="0.22334 0.672547 -0.216425 0.671536" mass="0.577943"
                  diaginertia="0.000797811 0.000747905 0.000457908"/>
        <joint name="RL_hip_joint" class="abduction"/>
        <geom size="0.039 0.0175" quat="0.707107 0.707107 0 0" type="cylinder" class="collision"/>
        <geom size="0.039 0.0175" pos="0 0.059 0" quat="0.707107 0.707107 0 0" type="cylinder" class="collision"/>
        <geom quat="0 0 1 0" type="mesh" class="visual" material="dark" mesh="abad"/>
        <body name="RL_hip" pos="0 0.094 0">
          <inertial pos="-0.00171622 -0.0276376 -0.0148955" quat="0.972561 0.187345 0.00546887 0.137833" mass="0.5954"
                    diaginertia="0.00125179 0.00120656 0.000449032"/>
          <joint name="RL_thigh_joint" class="back_hip"/>
          <geom size="0.06 0.0125 0.017" pos="0 0 -0.06" quat="0.707107 0 0.707107 0" type="box" class="collision"/>
          <geom type="mesh" class="visual" material="dark" mesh="hip"/>
          <body name="RL_knee" pos="0 0 -0.12">
            <inertial pos="0.00157271 -3.78302e-05 -0.106096" quat="0.708712 -0.0140225 -0.0146892 0.705206"
                      mass="0.144731" diaginertia="0.000843553 0.00083835 1.87502e-05"/>
            <joint name="RL_calf_joint" class="knee"/>
            <geom class="visual" material="metal" type="mesh" mesh="knee"/>
            <geom size="0.008 0.008 0.091705" pos="0 0 -0.091705" quat="0 0 1 0" type="box" class="collision"/>
            <geom name="RL_knee_rubber" size="0.016" pos="-0.01 0 -0.007" quat="0 0 1 0" class="collision"/>
            <geom size="0.019" pos="0.0055 0 -0.17391" class="collision"/>
            <site name="RL_touch" pos="0.0055 0 -0.17391" size="0.02" material="transparent"/>
          </body>
        </body>
      </body>
      <body name="RR_abad" pos="-0.164 -0.042 0">
        <inertial pos="0.00870249 -0.0262609 -0.00018743" quat="-0.22334 0.672547 0.216425 0.671536" mass="0.577943"
                  diaginertia="0.000797811 0.000747905 0.000457908"/>
        <joint name="RR_hip_joint" class="abduction"/>
        <geom size="0.039 0.0175" quat="0.707107 0.707107 0 0" type="cylinder" class="collision"/>
        <geom size="0.039 0.0175" pos="0 -0.059 0" quat="0.707107 0.707107 0 0" type="cylinder" class="collision"/>
        <geom quat="0 0 0 1" type="mesh" class="visual" material="dark" mesh="abad"/>
        <body name="RR_hip" pos="0 -0.094 0">
          <inertial pos="-0.00171622 0.0276376 -0.0148955" quat="0.972561 -0.187345 0.00546887 -0.137833" mass="0.5954"
                    diaginertia="0.00125179 0.00120656 0.000449032"/>
          <joint name="RR_thigh_joint" class="back_hip"/>
          <geom size="0.06 0.0125 0.017" pos="0 0 -0.06" quat="0.707107 0 0.707107 0" type="box" class="collision"/>
          <geom type="mesh" class="visual" material="dark" mesh="hip_mirror"/>
          <body name="RR_knee" pos="0 0 -0.12">
            <inertial pos="0.00157271 -3.78302e-05 -0.106096" quat="0.708712 -0.0140225 -0.0146892 0.705206"
                      mass="0.144731" diaginertia="0.000843553 0.00083835 1.87502e-05"/>
            <joint name="RR_calf_joint" class="knee"/>
            <geom class="visual" material="metal" type="mesh" mesh="knee"/>
            <geom size="0.008 0.008 0.091705" pos="0 0 -0.091705" quat="0 0 1 0" type="box" class="collision"/>
            <geom name="RR_knee_rubber" size="0.016" pos="-0.01 0 -0.007" quat="0 0 1 0" class="collision"/>
            <geom size="0.019" pos="0.0055 0 -0.17391" class="collision"/>
            <site name="RR_touch" pos="0.0055 0 -0.17391" size="0.02" material="transparent"/>
          </body>
        </body>
      </body>
    </body>
  </worldbody>

  <actuator>
    <motor class="abduction" name="FR_hip" joint="FR_hip_joint"/>
    <motor class="hip" name="FR_thigh" joint="FR_thigh_joint"/>
    <motor class="knee" name="FR_calf" joint="FR_calf_joint"/>
    <motor class="abduction" name="FL_hip" joint="FL_hip_joint"/>
    <motor class="hip" name="FL_thigh" joint="FL_thigh_joint"/>
    <motor class="knee" name="FL_calf" joint="FL_calf_joint"/>
    <motor class="abduction" name="RR_hip" joint="RR_hip_joint"/>
    <motor class="hip" name="RR_thigh" joint="RR_thigh_joint"/>
    <motor class="knee" name="RR_calf" joint="RR_calf_joint"/>
    <motor class="abduction" name="RL_hip" joint="RL_hip_joint"/>
    <motor class="hip" name="RL_thigh" joint="RL_thigh_joint"/>
    <motor class="knee" name="RL_calf" joint="RL_calf_joint"/>
  </actuator>

  <sensor>
    <jointpos name="FR_hip_pos" joint="FR_hip_joint"/>
    <jointpos name="FR_thigh_pos" joint="FR_thigh_joint"/>
    <jointpos name="FR_calf_pos" joint="FR_calf_joint"/>
    <jointpos name="FL_hip_pos" joint="FL_hip_joint"/>
    <jointpos name="FL_thigh_pos" joint="FL_thigh_joint"/>
    <jointpos name="FL_calf_pos" joint="FL_calf_joint"/>
    <jointpos name="RR_hip_pos" joint="RR_hip_joint"/>
    <jointpos name="RR_thigh_pos" joint="RR_thigh_joint"/>
    <jointpos name="RR_calf_pos" joint="RR_calf_joint"/>
    <jointpos name="RL_hip_pos" joint="RL_hip_joint"/>
    <jointpos name="RL_thigh_pos" joint="RL_thigh_joint"/>
    <jointpos name="RL_calf_pos" joint="RL_calf_joint"/>

    <jointvel name="FR_hip_vel" joint="FR_hip_joint"/>
    <jointvel name="FR_thigh_vel" joint="FR_thigh_joint"/>
    <jointvel name="FR_calf_vel" joint="FR_calf_joint"/>
    <jointvel name="FL_hip_vel" joint="FL_hip_joint"/>
    <jointvel name="FL_thigh_vel" joint="FL_thigh_joint"/>
    <jointvel name="FL_calf_vel" joint="FL_calf_joint"/>
    <jointvel name="RR_hip_vel" joint="RR_hip_joint"/>
    <jointvel name="RR_thigh_vel" joint="RR_thigh_joint"/>
    <jointvel name="RR_calf_vel" joint="RR_calf_joint"/>
    <jointvel name="RL_hip_vel" joint="RL_hip_joint"/>
    <jointvel name="RL_thigh_vel" joint="RL_thigh_joint"/>
    <jointvel name="RL_calf_vel" joint="RL_calf_joint"/>

    <jointactuatorfrc name="FR_hip_torque" joint="FR_hip_joint" noise="0.01"/>
    <jointactuatorfrc name="FR_thigh_torque" joint="FR_thigh_joint" noise="0.01"/>
    <jointactuatorfrc name="FR_calf_torque" joint="FR_calf_joint" noise="0.01"/>
    <jointactuatorfrc name="FL_hip_torque" joint="FL_hip_joint" noise="0.01"/>
    <jointactuatorfrc name="FL_thigh_torque" joint="FL_thigh_joint" noise="0.01"/>
    <jointactuatorfrc name="FL_calf_torque" joint="FL_calf_joint" noise="0.01"/>
    <jointactuatorfrc name="RR_hip_torque" joint="RR_hip_joint" noise="0.01"/>
    <jointactuatorfrc name="RR_thigh_torque" joint="RR_thigh_joint" noise="0.01"/>
    <jointactuatorfrc name="RR_calf_torque" joint="RR_calf_joint" noise="0.01"/>
    <jointactuatorfrc name="RL_hip_torque" joint="RL_hip_joint" noise="0.01"/>
    <jointactuatorfrc name="RL_thigh_torque" joint="RL_thigh_joint" noise="0.01"/>
    <jointactuatorfrc name="RL_calf_torque" joint="RL_calf_joint" noise="0.01"/>

    <framequat name="imu_quat" objtype="site" objname="imu"/>
    <gyro name="imu_gyro" site="imu"/>
    <accelerometer name="imu_acc" site="imu"/>

    <framepos name="frame_pos" objtype="site" objname="imu"/>
    <framelinvel name="frame_vel" objtype="site" objname="imu"/>

    <touch name="FR_touch" site="FR_touch"/>
    <touch name="FL_touch" site="FL_touch"/>
    <touch name="RR_touch" site="RR_touch"/>
    <touch name="RL_touch" site="RL_touch"/>
  </sensor>

  <keyframe>
    <key name="home" qpos="0 0 0.1 1 0 0 0 0.32 1.0 -2.53 -0.32 1.0 -2.53 0.32 1.0 -2.53 -0.32 1.0 -2.53"
         ctrl="0 0 0 0 0 0 0 0 0 0 0 0"/>
  </keyframe>
</mujoco>
