<mujoco model="CatModel2_v2">
  <compiler angle="radian" meshdir="assets" texturedir="assets" autolimits="true"/>

    <option cone="elliptic" impratio="100"/>

    <default>
    <default class="CatModel2_v2_fixed">
      <geom friction="0.4" margin="0.001" condim="1"/>
      <joint axis="0 1 0" damping="0.1" armature="0.01" frictionloss="0.2"/>
      <motor ctrlrange="-23.7 23.7"/>
      <default class="HAA">
        <joint axis="1 0 0" range="-0.785 0.785"/>
      </default>
      <default class="HFE">
        <joint range="-1.05 3.14"/>
      </default>
      <default class="KFE">
        <joint range="-2.68 -0.41"/>
        <motor ctrlrange="-47.4 47.4"/>
      </default>
      <default class="visual">
        <geom type="mesh" contype="0" conaffinity="0" group="2"/>
      </default>
      <default class="collision">
        <geom group="3" type="capsule"/>
        <default class="foot">
          <geom type="sphere" size="0.02" pos="-0.001 0 -0.18" priority="1" solimp="0.015 1 0.02" condim="6"
            friction="0.8 0.02 0.01"/>
        </default>
      </default>
    </default>
  </default>

  <asset>
    <material name="transparent" rgba="1 1 1 0.01" />
    <mesh name="base_link" file="base_link.obj"/>
    <mesh name="BF_Link" file="BF_Link.obj"/>
    <mesh name="BB_Link" file="BB_Link.obj"/>
    <mesh name="LF_hip" file="LF_hip.obj"/>
    <mesh name="LF_thigh" file="LF_thigh.obj"/>
    <mesh name="LF_calf" file="LF_calf.obj"/>
    <mesh name="RF_hip" file="RF_hip.obj"/>
    <mesh name="RF_thigh" file="RF_thigh.obj"/>
    <mesh name="RF_calf" file="RF_calf.obj"/>
    <mesh name="LH_hip" file="LH_hip.obj"/>
    <mesh name="LH_thigh" file="LH_thigh.obj"/>
    <mesh name="LH_calf" file="LH_calf.obj"/>
    <mesh name="RH_hip" file="RH_hip.obj"/>
    <mesh name="RH_thigh" file="RH_thigh.obj"/>
    <mesh name="RH_calf" file="RH_calf.obj"/>
  </asset>


  <worldbody>
    <body name="base_link" pos="0 0 0.4" childclass = "CatModel2_v2_fixed">
      <inertial pos="-0.0132868 -0.00105211 -0.00229256" quat="0.00190534 0.705549 0.00632194 0.70863" mass="6.70243" diaginertia="0.176112 0.165836 0.0262575"/>
      <joint name="floating_base" type="free" limited="false" actuatorfrclimited="false"/> 
      <geom mesh="base_link" class = "visual"/>
      <!-- <site name="imu" pos="0.00 0 0.06" quat="0.9990482 0 -0.044 0" /> -->
      <site name="imu" pos="0.00 0 0.06" />
      <geom mesh="BF_Link" class = "visual"/>
      <geom size="0.08 0.1 0.06" pos="0.13 0 0" type="box" rgba="0.752941 0.752941 0.752941 1" class = "collision"/>
      <geom mesh="BB_Link" class = "visual"/>
      <geom size="0.09 0.1 0.06" pos="-0.13 0 0" type="box" rgba="0.752941 0.752941 0.752941 1" class = "collision"/>
      <body name="LF_hip" pos="0.2106 0.05498 -0.000275">
        <inertial pos="0.059149 0.000487509 5.42937e-05" quat="0.493401 0.503185 0.506048 0.497268" mass="0.640228" diaginertia="0.000855628 0.000513713 0.000474779"/>
        <joint name="LF_HAA" class="HAA"/>
        <geom type="mesh" mesh="LF_hip" class="visual"/>
        <body name="LF_thigh" pos="0.065399 0.02005 0">
          <inertial pos="-0.00319263 0.0418747 -0.0295109" quat="0.713478 0.0874035 -0.0201842 0.694911" mass="0.902429" diaginertia="0.00430663 0.00400978 0.00078766"/>
          <joint name="LF_HFE" class="HFE"/>
          <geom type="mesh" mesh="LF_thigh" class="visual"/>
          <body name="LF_calf" pos="0 0.0617 -0.22">
            <inertial pos="0 0 -0.0526579" quat="0.707107 0 0 0.707107" mass="0.144759" diaginertia="0.00057453 0.0005605 3.075e-05"/>
            <joint name="LF_KFE" class="KFE"/>
            <geom mesh="LF_calf" class="visual" />
            <geom size="0.09 0.01 0.015" pos="0 0 -0.068" quat="0.707107 0 0.707107 0" type="box" class="collision"/>
            <geom class="foot"/>
            <site name="LF_touch" pos="0 0 -0.18" size="0.022" material="transparent"/>
          </body>
        </body>
      </body>
      <body name="RF_hip" pos="0.2106 -0.05502 -0.000275">
        <inertial pos="0.059149 -0.000487509 -5.42937e-05" quat="0.506048 0.497268 0.493401 0.503185" mass="0.640228" diaginertia="0.000855628 0.000513713 0.000474779"/>
        <joint name="RF_HAA" class="HAA"/>
        <geom mesh="RF_hip" class="visual"/>
        <body name="RF_thigh" pos="0.065399 -0.02005 0">
          <inertial pos="-0.00317858 -0.0418864 -0.0284744" quat="0.693082 -0.0185938 0.0908059 0.714875" mass="0.902429" diaginertia="0.00413894 0.00382908 0.000804188"/>
           <joint name="RF_HFE" class="HFE"/>
           <geom mesh="RF_thigh" class="visual"/>
          <body name="RF_calf" pos="0 -0.0617 -0.22">
            <inertial pos="0 0 -0.0526579" quat="0.707107 0 0 0.707107" mass="0.144759" diaginertia="0.00057453 0.0005605 3.075e-05"/>
            <joint name="RF_KFE" class="KFE"/>
            <geom mesh="RF_calf" class="visual"/>
            <geom size="0.09 0.01 0.015" pos="0 0 -0.068" quat="0.707107 0 0.707107 0" type="box" class="collision"/>
            <geom class="foot"/>
            <site name="RF_touch" pos="0 0 -0.18" size="0.022" material="transparent"/>
          </body>
        </body>
      </body>
      <body name="LH_hip" pos="-0.2306 0.05498 -0.00027501">
        <inertial pos="-0.059149 0.000487509 -5.42937e-05" quat="0.497268 0.506048 0.503185 0.493401" mass="0.640228" diaginertia="0.000855628 0.000513713 0.000474779"/>
        <joint name="LH_HAA" class="HAA"/>
        <geom mesh="LH_hip" class="visual"/>
        <body name="LH_thigh" pos="-0.065399 0.02005 0">
          <inertial pos="-0.00326546 0.0418747 -0.0284492" quat="0.712507 0.0909748 -0.0187807 0.695488" mass="0.902429" diaginertia="0.0041341 0.00382473 0.000802854"/>
          <joint name="LH_HFE" class="HFE"/>
          <geom mesh="LH_thigh" class="visual"/>
          <body name="LH_calf" pos="0 0.0617 -0.22">
            <inertial pos="0 0 -0.0526579" quat="0.707107 0 0 0.707107" mass="0.144759" diaginertia="0.00057453 0.0005605 3.075e-05"/>
            <joint name="LH_KFE" class="KFE"/>
            <geom mesh="LH_calf" class="visual"/>
            <geom size="0.09 0.01 0.015" pos="0 0 -0.068" quat="0.707107 0 0.707107 0" type="box" class="collision"/>
            <geom class="foot"/>
            <site name="LH_touch" pos="0 0 -0.18" size="0.022" material="transparent"/>
          </body>
        </body>
      </body>
      <body name="RH_hip" pos="-0.2306 -0.05502 -0.00027501">
        <inertial pos="-0.059149 -0.000487509 5.42937e-05" quat="0.491452 0.505813 0.509396 0.493096" mass="0.640228" diaginertia="0.000860842 0.000518309 0.000476"/>
        <joint name="RH_HAA" class="HAA"/>
        <geom mesh="RH_hip" class="visual"/>
        <body name="RH_thigh" pos="-0.065399 -0.02005 0">
          <inertial pos="-0.00317242 -0.0418864 -0.0284492" quat="0.693096 -0.0186609 0.0907935 0.714861" mass="0.902455" diaginertia="0.00413462 0.00382463 0.000804383"/>
          <joint name="RH_HFE" class="HFE"/>
          <geom mesh="RH_thigh" class="visual"/>
          <body name="RH_calf" pos="0 -0.0617 -0.22">
            <inertial pos="0 0 -0.0526579" quat="0.707107 0 0 0.707107" mass="0.144759" diaginertia="0.00057453 0.0005605 3.075e-05"/>
            <joint name="RH_KFE" class="KFE"/>
            <geom mesh="RH_calf" class="visual"/>
            <geom size="0.09 0.01 0.015" pos="0 0 -0.068" quat="0.707107 0 0.707107 0" type="box" class="collision"/>
            <geom class="foot"/>
            <site name="RH_touch" pos="0 0 -0.18" size="0.022" material="transparent"/>
          </body>
        </body>
      </body>
    </body>
  </worldbody>

    <actuator>
    <motor class="HAA" name="LH_HAA_motor" joint="LH_HAA" />
    <motor class="HFE" name="LH_HFE_motor" joint="LH_HFE" />
    <motor class="KFE" name="LH_KFE_motor" joint="LH_KFE" />
    <motor class="HAA" name="RH_HAA_motor" joint="RH_HAA" />
    <motor class="HFE" name="RH_HFE_motor" joint="RH_HFE" />
    <motor class="KFE" name="RH_KFE_motor" joint="RH_KFE" />
    <motor class="HAA" name="LF_HAA_motor" joint="LF_HAA" />
    <motor class="HFE" name="LF_HFE_motor" joint="LF_HFE" />
    <motor class="KFE" name="LF_KFE_motor" joint="LF_KFE" />
    <motor class="HAA" name="RF_HAA_motor" joint="RF_HAA" />
    <motor class="HFE" name="RF_HFE_motor" joint="RF_HFE" />
    <motor class="KFE" name="RF_KFE_motor" joint="RF_KFE" />
  </actuator>
  
  <sensor>

    <jointpos name="LH_HAA_pos" joint="LH_HAA"/>
    <jointpos name="LH_HFE_pos" joint="LH_HFE"/>
    <jointpos name="LH_KFE_pos" joint="LH_KFE"/>
    <jointpos name="RH_HAA_pos" joint="RH_HAA"/>
    <jointpos name="RH_HFE_pos" joint="RH_HFE"/>
    <jointpos name="RH_KFE_pos" joint="RH_KFE"/>

    <jointpos name="LF_HAA_pos" joint="LF_HAA"/>
    <jointpos name="LF_HFE_pos" joint="LF_HFE"/>
    <jointpos name="LF_KFE_pos" joint="LF_KFE"/>
    <jointpos name="RF_HAA_pos" joint="RF_HAA"/>
    <jointpos name="RF_HFE_pos" joint="RF_HFE"/>
    <jointpos name="RF_KFE_pos" joint="RF_KFE"/>


    <jointvel name="LH_HAA_vel" joint="LH_HAA"/>
    <jointvel name="LH_HFE_vel" joint="LH_HFE"/>
    <jointvel name="LH_KFE_vel" joint="LH_KFE"/>
    <jointvel name="RH_HAA_vel" joint="RH_HAA"/>
    <jointvel name="RH_HFE_vel" joint="RH_HFE"/>
    <jointvel name="RH_KFE_vel" joint="RH_KFE"/>

    <jointvel name="LF_HAA_vel" joint="LF_HAA"/>
    <jointvel name="LF_HFE_vel" joint="LF_HFE"/>
    <jointvel name="LF_KFE_vel" joint="LF_KFE"/>
    <jointvel name="RF_HAA_vel" joint="RF_HAA"/>
    <jointvel name="RF_HFE_vel" joint="RF_HFE"/>
    <jointvel name="RF_KFE_vel" joint="RF_KFE"/>



    
    <jointactuatorfrc name="LH_HAA_torque" joint="LH_HAA" noise="0.01"/>
    <jointactuatorfrc name="LH_HFE_torque" joint="LH_HFE" noise="0.01"/>
    <jointactuatorfrc name="LH_KFE_torque" joint="LH_KFE" noise="0.01"/>
    <jointactuatorfrc name="RH_HAA_torque" joint="RH_HAA" noise="0.01"/>
    <jointactuatorfrc name="RH_HFE_torque" joint="RH_HFE" noise="0.01"/>
    <jointactuatorfrc name="RH_KFE_torque" joint="RH_KFE" noise="0.01"/>
    
    <jointactuatorfrc name="LF_HAA_torque" joint="LF_HAA" noise="0.01"/>
    <jointactuatorfrc name="LF_HFE_torque" joint="LF_HFE" noise="0.01"/>
    <jointactuatorfrc name="LF_KFE_torque" joint="LF_KFE" noise="0.01"/>
    <jointactuatorfrc name="RF_HAA_torque" joint="RF_HAA" noise="0.01"/>
    <jointactuatorfrc name="RF_HFE_torque" joint="RF_HFE" noise="0.01"/>
    <jointactuatorfrc name="RF_KFE_torque" joint="RF_KFE" noise="0.01"/>

    <framequat name="imu_quat" objtype="site" objname="imu"/>
    <gyro name="imu_gyro" site="imu"/>
    <accelerometer name="imu_acc" site="imu"/>

    <framepos name="frame_pos" objtype="site" objname="imu"/>
    <framelinvel name="frame_vel" objtype="site" objname="imu"/>

    <touch name="LH_touch" site="LH_touch"/>
    <touch name="RH_touch" site="RH_touch"/>
    <touch name="LF_touch" site="LF_touch"/>
    <touch name="RF_touch" site="RF_touch"/>
  </sensor>

  <keyframe>
    <key name="home" qpos="0 0 0.15 1 0 0 0 0.4 1.2 -2.7 -0.4 1.2 -2.7 0.4 1.2 -2.7 -0.4 1.2 -2.7"
      ctrl=" 0 0 0 0 0 0 0 0 0 0 0 0 "/>
  </keyframe>
</mujoco>
