<?xml version="1.0" ?>

<robot name="CatModel2_v2">

<mujoco>
    <compiler discardvisual="false"/>
</mujoco>

  <link name="base_link">
    <inertial>
      <origin rpy="0 0 0" xyz="0.00277323920478634 -0.000683626781969177 0.000994370734501381"/>
      <mass value="0.292406383722703"/>
      <inertia ixx="0.000353654952753145" ixy="9.4552962455264E-08" ixz="-3.36996347862766E-07" iyy="0.000146330330531832" iyz="-4.70122276038072E-07" izz="0.000239971483372341"/>
    </inertial>
    <visual>
      <origin rpy="0 0 0" xyz="0 0 0"/>
      <geometry>
        <mesh filename="package://CatModel2_v2_description/meshes/base_link.obj"/>
      </geometry>
      <material name="">
        <color rgba="0.752941176470588 0.752941176470588 0.752941176470588 1"/>
      </material>
    </visual>
  </link>
  <link name="BF_Link">
    <inertial>
      <origin rpy="0 0 0" xyz="0.129546604821677 -8.38041245366239E-05 -0.00131410677564781"/>
      <mass value="3.17726086651402"/>
      <inertia ixx="0.00487762703978344" ixy="5.01750155065513E-06" ixz="2.05194635544087E-06" iyy="0.00436562868814791" iyz="-2.04092061410854E-06" izz="0.00633735096075252"/>
    </inertial>
    <visual>
      <origin rpy="0 0 0" xyz="0 0 0"/>
      <geometry>
        <mesh filename="package://CatModel2_v2_description/meshes/BF_Link.obj"/>
      </geometry>
      <material name="">
        <color rgba="0.752941176470588 0.752941176470588 0.752941176470588 1"/>
      </material>
    </visual>
    <collision>
      <origin rpy="0 0 0" xyz="0.13 0 0"/>
      <geometry>
        <box size="0.16 0.2 0.12"/>
      </geometry>
    </collision>
  </link>
  <joint name="bodyf_pitch_joint" type="revolute">
    <origin rpy="0 0 0" xyz="0 0 0"/>
    <parent link="base_link"/>
    <child link="BF_Link"/>
    <axis xyz="0 -1 0"/>
    <limit effort="23.7" lower="-0.75" upper="0.75" velocity="18"/>
  </joint>
  <link name="BB_Link">
    <inertial>
      <origin rpy="0 0 0" xyz="-0.155121047880281 -0.002037089893696 -0.00355151701603064"/>
      <mass value="3.23275137200683"/>
      <inertia ixx="0.00514719625702028" ixy="-1.1256522211618E-06" ixz="1.95082644973747E-08" iyy="0.00417841726459602" iyz="4.35796353082797E-06" izz="0.0068065106450055"/>
    </inertial>
    <visual>
      <origin rpy="0 0 0" xyz="0 0 0"/>
      <geometry>
        <mesh filename="package://CatModel2_v2_description/meshes/BB_Link.obj"/>
      </geometry>
      <material name="">
        <color rgba="0.752941176470588 0.752941176470588 0.752941176470588 1"/>
      </material>
    </visual>
    <collision>
      <origin rpy="0 0 0" xyz="-0.13 0 0"/>
      <geometry>
        <box size="0.18 0.2 0.12"/>
      </geometry>
    </collision>
  </link>
  <joint name="bodyb_yaw_joint" type="revolute">
    <origin rpy="0 0 0" xyz="0 0 0"/>
    <parent link="base_link"/>
    <child link="BB_Link"/>
    <axis xyz="0 0 1"/>
    <limit effort="23.7" lower="-0.75" upper="0.75" velocity="18"/>
  </joint>
  <link name="LF_hip">
    <inertial>
      <origin rpy="0 0 0" xyz="0.0591490581019897 0.000487525970476993 5.42903367247299E-05"/>
      <mass value="0.640225051482546"/>
      <inertia ixx="0.000434212543234904" ixy="7.35174336443465E-08" ixz="9.90921151291063E-07" iyy="0.000720360810738487" iyz="-6.90839528763486E-08" izz="0.000342952443359204"/>
    </inertial>
    <visual>
      <origin rpy="0 0 0" xyz="0 0 0"/>
      <geometry>
        <mesh filename="package://CatModel2_v2_description/meshes/LF_hip.obj"/>
      </geometry>
      <material name="">
        <color rgba="0.752941176470588 0.752941176470588 0.752941176470588 1"/>
      </material>
    </visual>
  </link>
  <joint name="LF_HAA" type="revolute">
    <origin rpy="0 0 0" xyz="0.2106 0.05498 -0.00027501"/>
    <parent link="BF_Link"/>
    <child link="LF_hip"/>
    <axis xyz="1 0 0"/>
    <limit effort="23.7" lower="-0.785" upper="0.785" velocity="18"/>
  </joint>
  <link name="LF_thigh">
    <inertial>
      <origin rpy="0 0 0" xyz="-0.0030739099306975 0.0445408222787197 -0.0334145744003372"/>
      <mass value="1.12465224029442"/>
      <inertia ixx="0.00245335338419425" ixy="2.12293216702249E-07" ixz="-0.000133463315750046" iyy="0.00307750016934983" iyz="5.10342287674753E-07" izz="0.000688894175100013"/>
    </inertial>
    <visual>
      <origin rpy="0 0 0" xyz="0 0 0"/>
      <geometry>
        <mesh filename="package://CatModel2_v2_description/meshes/LF_thigh.obj"/>
      </geometry>
      <material name="">
        <color rgba="0.752941176470588 0.752941176470588 0.752941176470588 1"/>
      </material>
    </visual>
  </link>
  <joint name="LF_HFE" type="revolute">
    <origin rpy="0 0 0" xyz="0.065399 0.02005 0"/>
    <parent link="LF_hip"/>
    <child link="LF_thigh"/>
    <axis xyz="0 1 0"/>
    <limit effort="23.7" lower="-1.05" upper="3.14" velocity="18"/>
  </joint>
  <link name="LF_calf">
    <inertial>
      <origin rpy="0 0 0" xyz="9.99200722162641E-16 -6.49480469405717E-15 -0.0480962091528342"/>
      <mass value="0.194979164491393"/>
      <inertia ixx="0.000446183487077817" ixy="-1.7009413190856E-20" ixz="-4.7709839570395E-19" iyy="0.00047353627001244" iyz="-3.08201650201865E-18" izz="3.05604232600862E-05"/>
    </inertial>
    <visual>
      <origin rpy="0 0 0" xyz="0 0 0"/>
      <geometry>
        <mesh filename="package://CatModel2_v2_description/meshes/LF_calf.obj"/>
      </geometry>
      <material name="">
        <color rgba="0.101960784313725 0.101960784313725 0.101960784313725 1"/>
      </material>
    </visual>
    <collision>
      <origin rpy="0 1.5707963267948966 0" xyz="0.0 0 -0.068"/>
      <geometry>
        <box size="0.18 0.02 0.03"/>
      </geometry>
    </collision>
  </link>
  <joint name="LF_KFE" type="revolute">
    <origin rpy="0 0 0" xyz="0 0.0617 -0.22"/>
    <parent link="LF_thigh"/>
    <child link="LF_calf"/>
    <axis xyz="0 1 0"/>
    <limit effort="23.7" lower="-2.70" upper="-0.92" velocity="18"/>
  </joint>
  <link name="LF_FOOT">
    <visual>
      <origin rpy="0 0 0" xyz="0 0 0"/>
      <geometry>
        <sphere radius="0.01"/>
      </geometry>
      <material name="">
        <color rgba="0.752941176470588 0.752941176470588 0.752941176470588 1"/>
      </material>
    </visual>
    <collision>
      <origin rpy="0 0 0" xyz="0 0 0"/>
      <geometry>
        <sphere radius="0.02"/>
      </geometry>
    </collision>
    <inertial>
      <mass value="0.06"/>
      <inertia ixx="9.600000000000001e-06" ixy="0.0" ixz="0.0" iyy="9.600000000000001e-06" iyz="0.0" izz="9.600000000000001e-06"/>
    </inertial>
  </link>
  <joint name="LF_foot_fixed" type="fixed">
    <origin rpy="0 0 0" xyz="-0.001 0 -0.18"/>
    <parent link="LF_calf"/>
    <child link="LF_FOOT"/>
  </joint>
  <link name="RF_hip">
    <inertial>
      <origin rpy="0 0 0" xyz="0.0591490581019896 -0.000487525970476951 -5.42903367248861E-05"/>
      <mass value="0.640225051482545"/>
      <inertia ixx="0.000434212543234904" ixy="-7.35174336445211E-08" ixz="-9.90921151292405E-07" iyy="0.000720360810738487" iyz="-6.90839528752694E-08" izz="0.000342952443359203"/>
    </inertial>
    <visual>
      <origin rpy="0 0 0" xyz="0 0 0"/>
      <geometry>
        <mesh filename="package://CatModel2_v2_description/meshes/RF_hip.obj"/>
      </geometry>
      <material name="">
        <color rgba="0.752941176470588 0.752941176470588 0.752941176470588 1"/>
      </material>
    </visual>
  </link>
  <joint name="RF_HAA" type="revolute">
    <origin rpy="0 0 0" xyz="0.2106 -0.05502 -0.00027501"/>
    <parent link="BF_Link"/>
    <child link="RF_hip"/>
    <axis xyz="1 0 0"/>
    <limit effort="23.7" lower="-0.785" upper="0.785" velocity="18"/>
  </joint>
  <link name="RF_thigh">
    <inertial>
      <origin rpy="0 0 0" xyz="-0.00294332106712775 -0.0445542922487313 -0.0333375777702376"/>
      <mass value="1.12465224794149"/>
      <inertia ixx="0.00245313302822235" ixy="2.12293243048377E-07" ixz="-0.000137640502846199" iyy="0.00307750017207129" iyz="7.49542308302712E-07" izz="0.000689114533903483"/>
    </inertial>
    <visual>
      <origin rpy="0 0 0" xyz="0 0 0"/>
      <geometry>
        <mesh filename="package://CatModel2_v2_description/meshes/RF_thigh.obj"/>
      </geometry>
      <material name="">
        <color rgba="0.752941176470588 0.752941176470588 0.752941176470588 1"/>
      </material>
    </visual>
  </link>
  <joint name="RF_HFE" type="revolute">
    <origin rpy="0 0 0" xyz="0.065399 -0.02005 0"/>
    <parent link="RF_hip"/>
    <child link="RF_thigh"/>
    <axis xyz="0 1 0"/>
    <limit effort="23.7" lower="-1.05" upper="3.14" velocity="18"/>
  </joint>
  <link name="RF_calf">
    <inertial>
      <origin rpy="0 0 0" xyz="-3.33066907387547E-16 -6.16173778666962E-15 -0.0480962091528168"/>
      <mass value="0.194979164491393"/>
      <inertia ixx="0.000446183487077817" ixy="-2.47430776246861E-20" ixz="-5.48286506056721E-19" iyy="0.00047353627001244" iyz="-2.56999394207267E-18" izz="3.05604232600862E-05"/>
    </inertial>
    <visual>
      <origin rpy="0 0 0" xyz="0 0 0"/>
      <geometry>
        <mesh filename="package://CatModel2_v2_description/meshes/RF_calf.obj"/>
      </geometry>
      <material name="">
        <color rgba="0.101960784313725 0.101960784313725 0.101960784313725 1"/>
      </material>
    </visual>
    <collision>
      <origin rpy="0 1.5707963267948966 0" xyz="0.0 0 -0.068"/>
      <geometry>
        <box size="0.18 0.02 0.03"/>
      </geometry>
    </collision>
  </link>
  <joint name="RF_KFE" type="revolute">
    <origin rpy="0 0 0" xyz="0 -0.0617 -0.22"/>
    <parent link="RF_thigh"/>
    <child link="RF_calf"/>
    <axis xyz="0 1 0"/>
    <limit effort="23.7" lower="-2.70" upper="-0.92" velocity="18"/>
  </joint>
  <link name="RF_FOOT">
    <visual>
      <origin rpy="0 0 0" xyz="0 0 0"/>
      <geometry>
        <sphere radius="0.01"/>
      </geometry>
      <material name="">
        <color rgba="0.752941176470588 0.752941176470588 0.752941176470588 1"/>
      </material>
    </visual>
    <collision>
      <origin rpy="0 0 0" xyz="0 0 0"/>
      <geometry>
        <sphere radius="0.02"/>
      </geometry>
    </collision>
    <inertial>
      <mass value="0.06"/>
      <inertia ixx="9.600000000000001e-06" ixy="0.0" ixz="0.0" iyy="9.600000000000001e-06" iyz="0.0" izz="9.600000000000001e-06"/>
    </inertial>
  </link>
  <joint name="RF_foot_fixed" type="fixed">
    <origin rpy="0 0 0" xyz="-0.001 0 -0.18"/>
    <parent link="RF_calf"/>
    <child link="RF_FOOT"/>
  </joint>
  <link name="LH_hip">
    <inertial>
      <origin rpy="0 0 0" xyz="-0.0591490581019897 0.000487525970476965 -5.42903367247438E-05"/>
      <mass value="0.64022505148254"/>
      <inertia ixx="0.000434212543234901" ixy="-7.35174336447593E-08" ixz="9.90921151293637E-07" iyy="0.000720360810738482" iyz="6.90839528781579E-08" izz="0.000342952443359201"/>
    </inertial>
    <visual>
      <origin rpy="0 0 0" xyz="0 0 0"/>
      <geometry>
        <mesh filename="package://CatModel2_v2_description/meshes/LH_hip.obj"/>
      </geometry>
      <material name="">
        <color rgba="0.752941176470588 0.752941176470588 0.752941176470588 1"/>
      </material>
    </visual>
  </link>
  <joint name="LH_HAA" type="revolute">
    <origin rpy="0 0 0" xyz="-0.2306 0.05498 -0.00027501"/>
    <parent link="BB_Link"/>
    <child link="LH_hip"/>
    <axis xyz="1 0 0"/>
    <limit effort="23.7" lower="-0.785" upper="0.785" velocity="18"/>
  </joint>
  <link name="LH_thigh">
    <inertial>
      <origin rpy="0 0 0" xyz="-0.00296459050700548 0.0445408224072723 -0.0333171801453849"/>
      <mass value="1.1246522487195"/>
      <inertia ixx="0.00245308553256917" ixy="2.12293244348725E-07" ixz="-0.000132591439610028" iyy="0.00307750017246793" iyz="5.10341499439468E-07" izz="0.000689162029964506"/>
    </inertial>
    <visual>
      <origin rpy="0 0 0" xyz="0 0 0"/>
      <geometry>
        <mesh filename="package://CatModel2_v2_description/meshes/LH_thigh.obj"/>
      </geometry>
      <material name="">
        <color rgba="0.752941176470588 0.752941176470588 0.752941176470588 1"/>
      </material>
    </visual>
  </link>
  <joint name="LH_HFE" type="revolute">
    <origin rpy="0 0 0" xyz="-0.065399 0.02005 0"/>
    <parent link="LH_hip"/>
    <child link="LH_thigh"/>
    <axis xyz="0 1 0"/>
    <limit effort="23.7" lower="-1.05" upper="3.14" velocity="18"/>
  </joint>
  <link name="LH_calf">
    <inertial>
      <origin rpy="0 0 0" xyz="7.7715611723761E-16 8.32667268468867E-16 -0.0480962091528122"/>
      <mass value="0.194979164491393"/>
      <inertia ixx="0.000446183487077817" ixy="-3.15040135188582E-20" ixz="-1.19459832796741E-20" iyy="0.00047353627001244" iyz="3.38137605213191E-18" izz="3.05604232600862E-05"/>
    </inertial>
    <visual>
      <origin rpy="0 0 0" xyz="0 0 0"/>
      <geometry>
        <mesh filename="package://CatModel2_v2_description/meshes/LH_calf.obj"/>
      </geometry>
      <material name="">
        <color rgba="0.101960784313725 0.101960784313725 0.101960784313725 1"/>
      </material>
    </visual>
    <collision>
      <origin rpy="0 1.5707963267948966 0" xyz="0.0 0 -0.068"/>
      <geometry>
        <box size="0.18 0.02 0.03"/>
      </geometry>
    </collision>
  </link>
  <joint name="LH_KFE" type="revolute">
    <origin rpy="0 0 0" xyz="0 0.0617 -0.22"/>
    <parent link="LH_thigh"/>
    <child link="LH_calf"/>
    <axis xyz="0 1 0"/>
    <limit effort="23.7" lower="-2.70" upper="-0.92" velocity="18"/>
  </joint>
  <link name="LH_FOOT">
    <visual>
      <origin rpy="0 0 0" xyz="0 0 0"/>
      <geometry>
        <sphere radius="0.01"/>
      </geometry>
      <material name="">
        <color rgba="0.752941176470588 0.752941176470588 0.752941176470588 1"/>
      </material>
    </visual>
    <collision>
      <origin rpy="0 0 0" xyz="0 0 0"/>
      <geometry>
        <sphere radius="0.02"/>
      </geometry>
    </collision>
    <inertial>
      <mass value="0.06"/>
      <inertia ixx="9.600000000000001e-06" ixy="0.0" ixz="0.0" iyy="9.600000000000001e-06" iyz="0.0" izz="9.600000000000001e-06"/>
    </inertial>
  </link>
  <joint name="LH_foot_fixed" type="fixed">
    <origin rpy="0 0 0" xyz="-0.001 0 -0.18"/>
    <parent link="LH_calf"/>
    <child link="LH_FOOT"/>
  </joint>
  <link name="RH_hip">
    <inertial>
      <origin rpy="0 0 0" xyz="-0.0589998656454741 -0.000506527943530191 -1.5897939432092E-05"/>
      <mass value="0.642366646261419"/>
      <inertia ixx="0.000434440011866329" ixy="7.35174336441177E-08" ixz="-9.90921151292078E-07" iyy="0.000720364692882" iyz="6.90839528753012E-08" izz="0.000343179911990631"/>
    </inertial>
    <visual>
      <origin rpy="0 0 0" xyz="0 0 0"/>
      <geometry>
        <mesh filename="package://CatModel2_v2_description/meshes/RH_hip.obj"/>
      </geometry>
      <material name="">
        <color rgba="0.752941176470588 0.752941176470588 0.752941176470588 1"/>
      </material>
    </visual>
  </link>
  <joint name="RH_HAA" type="revolute">
    <origin rpy="0 0 0" xyz="-0.2306 -0.05502 -0.00027501"/>
    <parent link="BB_Link"/>
    <child link="RH_hip"/>
    <axis xyz="1 0 0"/>
    <limit effort="23.7" lower="-0.785" upper="0.785" velocity="18"/>
  </joint>
  <link name="RH_thigh">
    <inertial>
      <origin rpy="0 0 0" xyz="-0.00291911918187815 -0.0445542922605851 -0.0333171801453903"/>
      <mass value="1.12465224871951"/>
      <inertia ixx="0.00245308553256918" ixy="2.12293244349653E-07" ixz="-0.000137449014414576" iyy="0.00307750017246793" iyz="7.49542137911982E-07" izz="0.000689162029964504"/>
    </inertial>
    <visual>
      <origin rpy="0 0 0" xyz="0 0 0"/>
      <geometry>
        <mesh filename="package://CatModel2_v2_description/meshes/RH_thigh.obj"/>
      </geometry>
      <material name="">
        <color rgba="0.752941176470588 0.752941176470588 0.752941176470588 1"/>
      </material>
    </visual>
  </link>
  <joint name="RH_HFE" type="revolute">
    <origin rpy="0 0 0" xyz="-0.065399 -0.02005 0"/>
    <parent link="RH_hip"/>
    <child link="RH_thigh"/>
    <axis xyz="0 1 0"/>
    <limit effort="23.7" lower="-1.05" upper="3.14" velocity="18"/>
  </joint>
  <link name="RH_calf">
    <inertial>
      <origin rpy="0 0 0" xyz="4.44089209850063E-16 8.74300631892311E-16 -0.0480962091528153"/>
      <mass value="0.194979164491393"/>
      <inertia ixx="0.000446183487077817" ixy="-2.63781324388593E-21" ixz="7.53974201758945E-21" iyy="0.00047353627001244" iyz="2.9028260250883E-18" izz="3.05604232600862E-05"/>
    </inertial>
    <visual>
      <origin rpy="0 0 0" xyz="0 0 0"/>
      <geometry>
        <mesh filename="package://CatModel2_v2_description/meshes/RH_calf.obj"/>
      </geometry>
      <material name="">
        <color rgba="0.101960784313725 0.101960784313725 0.101960784313725 1"/>
      </material>
    </visual>
    <collision>
      <origin rpy="0 1.5707963267948966 0" xyz="0.0 0 -0.068"/>
      <geometry>
        <box size="0.18 0.02 0.03"/>
      </geometry>
    </collision>
  </link>
  <joint name="RH_KFE" type="revolute">
    <origin rpy="0 0 0" xyz="0 -0.0617 -0.22"/>
    <parent link="RH_thigh"/>
    <child link="RH_calf"/>
    <axis xyz="0 1 0"/>
    <limit effort="23.7" lower="-2.70" upper="-0.92" velocity="18"/>
  </joint>
  <link name="RH_FOOT">
    <visual>
      <origin rpy="0 0 0" xyz="0 0 0"/>
      <geometry>
        <sphere radius="0.01"/>
      </geometry>
      <material name="">
        <color rgba="0.752941176470588 0.752941176470588 0.752941176470588 1"/>
      </material>
    </visual>
    <collision>
      <origin rpy="0 0 0" xyz="0 0 0"/>
      <geometry>
        <sphere radius="0.02"/>
      </geometry>
    </collision>
    <inertial>
      <mass value="0.06"/>
      <inertia ixx="9.600000000000001e-06" ixy="0.0" ixz="0.0" iyy="9.600000000000001e-06" iyz="0.0" izz="9.600000000000001e-06"/>
    </inertial>
  </link>
  <joint name="RH_foot_fixed" type="fixed">
    <origin rpy="0 0 0" xyz="-0.001 0 -0.18"/>
    <parent link="RH_calf"/>
    <child link="RH_FOOT"/>
  </joint>

</robot>

