<mujoco model="aliengo">
	<compiler angle="radian" meshdir="meshes/"/>

	<default>
		<default class="aliengo">
			<geom friction="0.4" margin="0.001" condim="1"/>
			<joint axis="0 1 0" damping="0.1" armature="0.01" frictionloss="0.2"/>
			<motor ctrlrange="-35.278 35.278"/>
			<default class="abduction">
				<joint axis="1 0 0" range="-1.2211 1.2211"/>
			</default>
			<default class="hip">
				<joint range="-2.093 4.187"/>
			</default>
			<default class="knee">
				<joint range="-2.7737 -0.6454"/>
				<motor ctrlrange="-44.4 44.4"/>
			</default>
			<default class="visual">
				<geom type="mesh" contype="0" conaffinity="0" group="2" material="dark"/>
			</default>
			<default class="collision">
				<geom group="3"/>
				<default class="foot">
					<geom size="0.022" pos="-0.002 0 -0.213" priority="1" condim="6"
								friction="0.4 0.02 0.01"/>
				</default>
			</default>
		</default>
	</default>

	<asset>
		<material name="metal" rgba=".5 .5 .5 1" shininess="0.25" specular="0"/>
		<material name="black" rgba=".1 .1 .1 1" shininess="0.25"/>
		<material name="dark" rgba="0.2 0.2 0.2 1" shininess="0.1"/>
		<material name="transparent" rgba="1 1 1 0.01"/>

		<mesh name="trunk" file="trunk.stl"/>
		<mesh name="hip" file="hip.stl"/>
		<mesh name="thigh_mirror" file="thigh_mirror.stl"/>
		<mesh name="calf" file="calf.stl" scale="0.026 0.026 0.026"/>
		<mesh name="thigh" file="thigh.stl"/>
	</asset>

	<worldbody>
		<body name="base_link" pos="0 0 0.535" childclass="aliengo">
			<inertial pos="0.008811 0.003839 0.000273" quat="0 0 0 1"
								mass="11.644"
								diaginertia="0.107027 0.0980771 0.0244531"/>
			<freejoint/>
			<geom size="0.0005 0.0005 0.0005" type="box" contype="0" conaffinity="0" group="1" density="0"/>
			<geom type="mesh" class="visual" material="black" mesh="trunk"/>
			<geom size="0.3235 0.075 0.056" type="box" class="collision"/>
			<geom size="0.0005 0.0005 0.0005" type="box" contype="0" conaffinity="0" group="1" density="0"
						class="collision"/>
			<geom size="0.0005 0.0005 0.0005" type="box" class="collision"/>
			<geom size="0.035 0.01" pos="0.139985 -0.051 0" quat="0.707107 0 0.707107 0" type="cylinder" contype="0"
						conaffinity="0" group="1" density="0" rgba="0 0.8 0 1"/>
			<geom size="0.035 0.01" pos="0.139985 0.051 0" quat="0.707107 0 0.707107 0" type="cylinder" contype="0"
						conaffinity="0" group="1" density="0" rgba="0 0.8 0 1"/>
			<geom size="0.035 0.01" pos="-0.139985 -0.051 0" quat="0.707107 0 0.707107 0" type="cylinder" contype="0"
						conaffinity="0" group="1" density="0" rgba="0 0.8 0 1"/>
			<geom size="0.035 0.01" pos="-0.139985 0.051 0" quat="0.707107 0 0.707107 0" type="cylinder" contype="0"
						conaffinity="0" group="1" density="0" rgba="0 0.8 0 1"/>
			<site name="imu" pos="0 0 0"/>
			<body name="FL_hip" pos="0.2407 0.051 0">
				<inertial pos="-0.0206763 0.0161444 -1.39762e-05" quat="0.402465 0.412459 0.574831 0.58092" mass="2.139"
									diaginertia="0.0043606 0.0043277 0.00233028"/>
				<joint name="FL_hip_joint" pos="0 0 0" axis="1 0 0" range="-1.22173 1.22173"
							 actuatorfrcrange="-35.278 35.278"/>
				<geom type="mesh" class="visual" material="dark" mesh="hip"/>
				<geom size="0.046 0.0209" pos="0 0.083 0" quat="0.707107 0.707107 0 0" type="cylinder"
							class="collision"/>
				<geom size="0.035 0.01" pos="0 0.0298 0" quat="0.707107 0.707107 0 0" type="cylinder" contype="0"
							conaffinity="0" group="1" density="0" class="collision"/>
				<body name="FL_thigh" pos="0 0.0868 0">
					<inertial pos="-0.00464705 -0.0202825 -0.039947" quat="0.994998 0.0906147 0.0414285 0.0071304"
										mass="0.771" diaginertia="0.00560787 0.004847 0.00135111"/>
					<joint name="FL_thigh_joint" pos="0 0 0" axis="0 1 0" actuatorfrcrange="-35.278 35.278"/>
					<geom type="mesh" class="visual" material="dark" mesh="thigh"/>
					<geom size="0.125 0.0187 0.0215" pos="0 0 -0.125" quat="0.707107 0 0.707107 0" type="box"
								class="collision"/>
					<geom size="0.035 0.01" pos="0 -0.0997 0" quat="0.707107 0.707107 0 0" type="cylinder" contype="0"
								conaffinity="0" group="1" density="0" class="collision"/>
					<body name="FL_calf" pos="0 0 -0.25">
						<inertial pos="0.00215606 4.88427e-05 -0.166671" quat="0.708049 0.000982931 0.00120829 0.706161"
											mass="0.267" diaginertia="0.00269606 0.00268354 5.47714e-05"/>
						<joint name="FL_calf_joint" pos="0 0 0" axis="0 1 0" range="-2.77507 -0.645772"
									 actuatorfrcrange="-44.4 44.4"/>
						<geom class="visual" material="metal" type="mesh" mesh="calf"/>
						<geom size="0.125 0.0104 0.008" pos="0 0 -0.125" quat="0.707107 0 0.707107 0" type="box"
									class="collision"/>
						<geom size="0.0265" pos="0 0 -0.25" class="collision"/>
						<site name="FL_touch" pos="0 0 -0.25" size="0.03" material="transparent"/>
					</body>
				</body>
			</body>
			<body name="FR_hip" pos="0.2407 -0.051 0">
				<inertial pos="-0.0206763 -0.0161444 -1.39762e-05" quat="0.58092 0.574831 0.412459 0.402465"
									mass="2.139" diaginertia="0.0043606 0.0043277 0.00233028"/>
				<joint name="FR_hip_joint" pos="0 0 0" axis="1 0 0" range="-1.22173 1.22173"
							 actuatorfrcrange="-35.278 35.278"/>
				<geom quat="0 1 0 0" type="mesh" class="visual" material="dark" mesh="hip"/>
				<geom size="0.046 0.0209" pos="0 -0.083 0" quat="0.707107 0.707107 0 0" type="cylinder"
							class="collision"/>
				<geom size="0.035 0.01" pos="0 -0.0298 0" quat="0.707107 0.707107 0 0" type="cylinder" contype="0"
							conaffinity="0" group="1" density="0" class="collision"/>
				<body name="FR_thigh" pos="0 -0.0868 0">
					<inertial pos="-0.00464705 0.0202825 -0.039947" quat="0.994998 -0.0906147 0.0414285 -0.0071304"
										mass="0.771" diaginertia="0.00560787 0.004847 0.00135111"/>
					<joint name="FR_thigh_joint" pos="0 0 0" axis="0 1 0" actuatorfrcrange="-35.278 35.278"/>
					<geom type="mesh" class="visual" material="dark" mesh="thigh_mirror"/>
					<geom size="0.125 0.0187 0.0215" pos="0 0 -0.125" quat="0.707107 0 0.707107 0" type="box"
								class="collision"/>
					<geom size="0.035 0.01" pos="0 0.0997 0" quat="0.707107 0.707107 0 0" type="cylinder" contype="0"
								conaffinity="0" group="1" density="0" class="collision"/>
					<body name="FR_calf" pos="0 0 -0.25">
						<inertial pos="0.00215606 4.88427e-05 -0.166671" quat="0.708049 0.000982931 0.00120829 0.706161"
											mass="0.267" diaginertia="0.00269606 0.00268354 5.47714e-05"/>
						<joint name="FR_calf_joint" pos="0 0 0" axis="0 1 0" range="-2.77507 -0.645772"
									 actuatorfrcrange="-44.4 44.4"/>
						<geom class="visual" material="metal" type="mesh" mesh="calf"/>
						<geom size="0.125 0.0104 0.008" pos="0 0 -0.125" quat="0.707107 0 0.707107 0" type="box"
									class="collision"/>
						<geom size="0.0265" pos="0 0 -0.25" class="collision"/>
						<site name="FR_touch" pos="0 0 -0.25" size="0.03" material="transparent"/>
					</body>
				</body>
			</body>
			<body name="RL_hip" pos="-0.2407 0.051 0">
				<inertial pos="0.0206763 0.0161444 -1.39762e-05" quat="0.574831 0.58092 0.402465 0.412459" mass="2.139"
									diaginertia="0.0043606 0.0043277 0.00233028"/>
				<joint name="RL_hip_joint" pos="0 0 0" axis="1 0 0" range="-1.22173 1.22173"
							 actuatorfrcrange="-35.278 35.278"/>
				<geom quat="0 0 1 0" type="mesh" class="visual" material="dark" mesh="hip"/>
				<geom size="0.046 0.0209" pos="0 0.083 0" quat="0.707107 0.707107 0 0" type="cylinder"
							class="collision"/>
				<geom size="0.035 0.01" pos="0 0.0298 0" quat="0.707107 0.707107 0 0" type="cylinder" contype="0"
							conaffinity="0" group="1" density="0" class="collision"/>
				<body name="RL_thigh" pos="0 0.0868 0">
					<inertial pos="-0.00464705 -0.0202825 -0.039947" quat="0.994998 0.0906147 0.0414285 0.0071304"
										mass="0.771" diaginertia="0.00560787 0.004847 0.00135111"/>
					<joint name="RL_thigh_joint" pos="0 0 0" axis="0 1 0" actuatorfrcrange="-35.278 35.278"/>
					<geom type="mesh" class="visual" material="dark" mesh="thigh"/>
					<geom size="0.125 0.0187 0.0215" pos="0 0 -0.125" quat="0.707107 0 0.707107 0" type="box"
								class="collision"/>
					<geom size="0.035 0.01" pos="0 -0.0997 0" quat="0.707107 0.707107 0 0" type="cylinder" contype="0"
								conaffinity="0" group="1" density="0" class="collision"/>
					<body name="RL_calf" pos="0 0 -0.25">
						<inertial pos="0.00215606 4.88427e-05 -0.166671" quat="0.708049 0.000982931 0.00120829 0.706161"
											mass="0.267" diaginertia="0.00269606 0.00268354 5.47714e-05"/>
						<joint name="RL_calf_joint" pos="0 0 0" axis="0 1 0" range="-2.77507 -0.645772"
									 actuatorfrcrange="-44.4 44.4"/>
						<geom class="visual" material="metal" type="mesh" mesh="calf"/>
						<geom size="0.125 0.0104 0.008" pos="0 0 -0.125" quat="0.707107 0 0.707107 0" type="box"
									class="collision"/>
						<geom size="0.0265" pos="0 0 -0.25" class="collision"/>
						<site name="RL_touch" pos="0 0 -0.25" size="0.03" material="transparent"/>
					</body>
				</body>
			</body>
			<body name="RR_hip" pos="-0.2407 -0.051 0">
				<inertial pos="0.0206763 -0.0161444 -1.39762e-05" quat="0.412459 0.402465 0.58092 0.574831" mass="2.139"
									diaginertia="0.0043606 0.0043277 0.00233028"/>
				<joint name="RR_hip_joint" pos="0 0 0" axis="1 0 0" range="-1.22173 1.22173"
							 actuatorfrcrange="-35.278 35.278"/>
				<geom quat="0 0 0 -1" type="mesh" class="visual" material="dark" mesh="hip"/>
				<geom size="0.046 0.0209" pos="0 -0.083 0" quat="0.707107 0.707107 0 0" type="cylinder"
							class="collision"/>
				<geom size="0.035 0.01" pos="0 -0.0298 0" quat="0.707107 0.707107 0 0" type="cylinder"
							class="collision"/>
				<body name="RR_thigh" pos="0 -0.0868 0">
					<inertial pos="-0.00464705 0.0202825 -0.039947" quat="0.994998 -0.0906147 0.0414285 -0.0071304"
										mass="0.771" diaginertia="0.00560787 0.004847 0.00135111"/>
					<joint name="RR_thigh_joint" pos="0 0 0" axis="0 1 0" actuatorfrcrange="-35.278 35.278"/>
					<geom type="mesh" class="visual" material="dark" mesh="thigh_mirror"/>
					<geom size="0.125 0.0187 0.0215" pos="0 0 -0.125" quat="0.707107 0 0.707107 0" type="box"
								class="collision"/>
					<geom size="0.035 0.01" pos="0 0.0997 0" quat="0.707107 0.707107 0 0" type="cylinder" contype="0"
								conaffinity="0" group="1" density="0" class="collision"/>
					<body name="RR_calf" pos="0 0 -0.25">
						<inertial pos="0.00215606 4.88427e-05 -0.166671" quat="0.708049 0.000982931 0.00120829 0.706161"
											mass="0.267" diaginertia="0.00269606 0.00268354 5.47714e-05"/>
						<joint name="RR_calf_joint" pos="0 0 0" axis="0 1 0" range="-2.77507 -0.645772"
									 actuatorfrcrange="-44.4 44.4"/>
						<geom class="visual" material="metal" type="mesh" mesh="calf"/>
						<geom size="0.125 0.0104 0.008" pos="0 0 -0.125" quat="0.707107 0 0.707107 0" type="box"
									class="collision"/>
						<geom size="0.0265" pos="0 0 -0.25" class="collision"/>
						<site name="RR_touch" pos="0 0 -0.25" size="0.03" material="transparent"/>
					</body>
				</body>
			</body>
		</body>
	</worldbody>

	<actuator>
		<motor class="abduction" name="FR_hip" joint="FR_hip_joint"/>
		<motor class="hip" name="FR_thigh" joint="FR_thigh_joint"/>
		<motor class="knee" name="FR_calf" joint="FR_calf_joint"/>
		<motor class="abduction" name="FL_hip" joint="FL_hip_joint"/>
		<motor class="hip" name="FL_thigh" joint="FL_thigh_joint"/>
		<motor class="knee" name="FL_calf" joint="FL_calf_joint"/>
		<motor class="abduction" name="RR_hip" joint="RR_hip_joint"/>
		<motor class="hip" name="RR_thigh" joint="RR_thigh_joint"/>
		<motor class="knee" name="RR_calf" joint="RR_calf_joint"/>
		<motor class="abduction" name="RL_hip" joint="RL_hip_joint"/>
		<motor class="hip" name="RL_thigh" joint="RL_thigh_joint"/>
		<motor class="knee" name="RL_calf" joint="RL_calf_joint"/>
	</actuator>

	<sensor>
		<jointpos name="FR_hip_pos" joint="FR_hip_joint"/>
		<jointpos name="FR_thigh_pos" joint="FR_thigh_joint"/>
		<jointpos name="FR_calf_pos" joint="FR_calf_joint"/>
		<jointpos name="FL_hip_pos" joint="FL_hip_joint"/>
		<jointpos name="FL_thigh_pos" joint="FL_thigh_joint"/>
		<jointpos name="FL_calf_pos" joint="FL_calf_joint"/>
		<jointpos name="RR_hip_pos" joint="RR_hip_joint"/>
		<jointpos name="RR_thigh_pos" joint="RR_thigh_joint"/>
		<jointpos name="RR_calf_pos" joint="RR_calf_joint"/>
		<jointpos name="RL_hip_pos" joint="RL_hip_joint"/>
		<jointpos name="RL_thigh_pos" joint="RL_thigh_joint"/>
		<jointpos name="RL_calf_pos" joint="RL_calf_joint"/>

		<jointvel name="FR_hip_vel" joint="FR_hip_joint"/>
		<jointvel name="FR_thigh_vel" joint="FR_thigh_joint"/>
		<jointvel name="FR_calf_vel" joint="FR_calf_joint"/>
		<jointvel name="FL_hip_vel" joint="FL_hip_joint"/>
		<jointvel name="FL_thigh_vel" joint="FL_thigh_joint"/>
		<jointvel name="FL_calf_vel" joint="FL_calf_joint"/>
		<jointvel name="RR_hip_vel" joint="RR_hip_joint"/>
		<jointvel name="RR_thigh_vel" joint="RR_thigh_joint"/>
		<jointvel name="RR_calf_vel" joint="RR_calf_joint"/>
		<jointvel name="RL_hip_vel" joint="RL_hip_joint"/>
		<jointvel name="RL_thigh_vel" joint="RL_thigh_joint"/>
		<jointvel name="RL_calf_vel" joint="RL_calf_joint"/>

		<jointactuatorfrc name="FR_hip_torque" joint="FR_hip_joint" noise="0.01"/>
		<jointactuatorfrc name="FR_thigh_torque" joint="FR_thigh_joint" noise="0.01"/>
		<jointactuatorfrc name="FR_calf_torque" joint="FR_calf_joint" noise="0.01"/>
		<jointactuatorfrc name="FL_hip_torque" joint="FL_hip_joint" noise="0.01"/>
		<jointactuatorfrc name="FL_thigh_torque" joint="FL_thigh_joint" noise="0.01"/>
		<jointactuatorfrc name="FL_calf_torque" joint="FL_calf_joint" noise="0.01"/>
		<jointactuatorfrc name="RR_hip_torque" joint="RR_hip_joint" noise="0.01"/>
		<jointactuatorfrc name="RR_thigh_torque" joint="RR_thigh_joint" noise="0.01"/>
		<jointactuatorfrc name="RR_calf_torque" joint="RR_calf_joint" noise="0.01"/>
		<jointactuatorfrc name="RL_hip_torque" joint="RL_hip_joint" noise="0.01"/>
		<jointactuatorfrc name="RL_thigh_torque" joint="RL_thigh_joint" noise="0.01"/>
		<jointactuatorfrc name="RL_calf_torque" joint="RL_calf_joint" noise="0.01"/>

		<framequat name="imu_quat" objtype="site" objname="imu"/>
		<gyro name="imu_gyro" site="imu"/>
		<accelerometer name="imu_acc" site="imu"/>

		<framepos name="frame_pos" objtype="site" objname="imu"/>
		<framelinvel name="frame_vel" objtype="site" objname="imu"/>

		<touch name="FR_touch" site="FR_touch"/>
		<touch name="FL_touch" site="FL_touch"/>
		<touch name="RR_touch" site="RR_touch"/>
		<touch name="RL_touch" site="RL_touch"/>
	</sensor>

	<keyframe>
		<key name="home" qpos="0 0 0.1 1 0 0 0 0.5 1.2 -2.7 -0.5 1.2 -2.7 0.5 1.2 -2.7 -0.5 1.2 -2.7"
				 ctrl="0 0 0 0 0 0 0 0 0 0 0 0"/>
	</keyframe>
</mujoco>
