<?xml version="1.0" ?>

<robot name="CatModel2">

<mujoco>
    <compiler discardvisual="false"/>
</mujoco>

  <link name="cross">
    <inertial>
      <origin rpy="0 0 0" xyz="0 0 0"/>
      <mass value="0.10303"/>
      <inertia ixx="130343.98E-09" ixy="0.00" ixz="0.00" iyy="65743.25E-09" iyz="0.00" izz="65743.25E-09"/>
    </inertial>
    <visual>
      <origin rpy="0 0 0" xyz="0 0 0"/>
      <geometry>
        <mesh filename="package://CatModel2_description/meshes/cross.STL"/>
      </geometry>
      <material name="">
        <color rgba="0.752941176470588 0.752941176470588 0.752941176470588 1"/>
      </material>
    </visual>
    <collision>
      <origin rpy="0 0 0" xyz="0 0 0"/>
      <geometry>
        <box size="0.011 0.03 0.13"/>
      </geometry>
    </collision>
    <collision>
      <origin rpy="1.5707963267948966 0 0" xyz="0 0 0"/>
      <geometry>
        <box size="0.011 0.03 0.13"/>
      </geometry>
    </collision>    
  </link>
  
  <link name="chest">
    <inertial>
      <origin rpy="0 0 0" xyz="110.71E-03 0.08E-03 -0.04E-03"/>
      <mass value="2.10511"/>
      <inertia ixx="8222410.49E-09" ixy="1816.97E-09" ixz="7419.74E-09" iyy="8511204.33E-09" iyz="-757.05E-09" izz="11159274.40E-09"/>
    </inertial>
    <visual>
      <origin rpy="0 0 0" xyz="0 0 0"/>
      <geometry>
        <mesh filename="package://CatModel2_description/meshes/chest.STL"/>
      </geometry>
      <material name="">
        <color rgba="0.752941176470588 0.752941176470588 0.752941176470588 1"/>
      </material>
    </visual>
    <collision>
      <origin rpy="0 0 0" xyz="0.12 0 0"/>
      <geometry>
        <box size="0.128 0.195 0.148"/>
      </geometry>
    </collision>
  </link>
  
  <joint name="Base_joint" type="revolute">
    <origin rpy="0 0 0" xyz="0 0 0"/>
    <parent link="cross"/>
    <child link="chest"/>
    <axis xyz="0 0 1"/>
    <!-- <dynamics damping="0.1" friction="0.1"/> -->
    <limit effort="100" lower="-0.75" upper="0.75" velocity="18"/>
  </joint>

  <link name="LF_hip">
    <inertial>
      <origin rpy="0 0 0" xyz="-3.06E-03 -15.19E-03 0.23E-03"/>
      <mass value="0.31877"/>
      <inertia ixx="150729.95E-09" ixy="-14678.35E-09" ixz="-199.51E-09" iyy="169042.16E-09" iyz="1282.75E-09" izz="175802.90E-09"/>
    </inertial>
    <visual>
      <origin rpy="0 0 0" xyz="0 0 0"/>
      <geometry>
        <mesh filename="package://CatModel2_description/meshes/LF_hip.STL"/>
      </geometry>
      <material name="">
        <color rgba="0.752941176470588 0.752941176470588 0.752941176470588 1"/>
      </material>
    </visual>
    <!-- <collision>
      <origin rpy="1.5707963267948966 0 0" xyz="0 -0.01 0"/>
      <geometry>
        <cylinder length="0.07" radius="0.028"/>
      </geometry>
    </collision> -->
  </link>
  <joint name="LF_HAA" type="revolute">
    <origin rpy="0 0 0" xyz="0.215 0.0649999999999998 0"/>
    <parent link="chest"/>
    <child link="LF_hip"/>
    <axis xyz="1 0 0"/>
    <limit effort="33.5" lower="-0.785" upper="0.785" velocity="18"/>
  </joint>
  <link name="LF_thigh">
    <inertial>
      <origin rpy="0 0 0" xyz="-0.02E-03 -23.50E-03 -19.36E-03"/>
      <mass value="0.57287"/>
      <inertia ixx="1472878.77E-09" ixy="197.96E-09" ixz="237.97E-09" iyy="1312622.06E-09" iyz="260046.65E-09" izz="443726.89E-09"/>
    </inertial>
    <visual>
      <origin rpy="0 0 0" xyz="0 0 0"/>
      <geometry>
        <mesh filename="package://CatModel2_description/meshes/LF_thigh.STL"/>
      </geometry>
      <material name="">
        <color rgba="0.752941176470588 0.752941176470588 0.752941176470588 1"/>
      </material>
    </visual>
    <!-- <collision>
      <origin rpy="0 1.5707963267948966 0" xyz="0 0 -0.07"/>
      <geometry>
        <box size="0.18 0.025 0.03"/>
      </geometry>
    </collision>
    <collision>
      <origin rpy="1.5707963267948966 0 0" xyz="0 -0.015 0"/>
      <geometry>
        <cylinder length="0.053" radius="0.028"/>
      </geometry>
    </collision> -->
  </link>
  <joint name="LF_HFE" type="revolute">
    <origin rpy="0 0 0" xyz="0 0.072 0"/>
    <parent link="LF_hip"/>
    <child link="LF_thigh"/>
    <axis xyz="0 1 0"/>
    <limit effort="33.5" lower="-1.05" upper="3.14" velocity="18"/>
  </joint>
  <link name="LF_calf">
    <inertial>
      <origin rpy="0 0 0" xyz="0.0 0.0 -65.28E-03"/>
      <mass value="0.09192"/>
      <inertia ixx="414588.70E-09" ixy="0.00" ixz="0.00E-09" iyy="418880.65E-09" iyz="18.08E-09" izz="10670.32E-09"/>
    </inertial>
    <visual>
      <origin rpy="0 0 0" xyz="0 0 0"/>
      <geometry>
        <mesh filename="package://CatModel2_description/meshes/LF_calf.STL"/>
      </geometry>
      <material name="">
        <color rgba="0.752941176470588 0.752941176470588 0.752941176470588 1"/>
      </material>
    </visual>
    <collision>
      <origin rpy="0 1.5707963267948966 0" xyz="0.0 0 -0.05"/>
      <geometry>
        <box size="0.14 0.018 0.025"/>
      </geometry>
    </collision>
  </link>
  <joint name="LF_KFE" type="revolute">
    <origin rpy="0 0 0" xyz="0 0 -0.164"/>
    <parent link="LF_thigh"/>
    <child link="LF_calf"/>
    <axis xyz="0 1 0"/>
    <limit effort="33.5" lower="-2.70" upper="-0.92" velocity="18"/>
  </joint>
  <link name="LF_FOOT">
    <visual>
      <origin rpy="0 0 0" xyz="0 0 0"/>
      <geometry>
        <sphere radius="0.01"/>
      </geometry>
      <material name="">
        <color rgba="0.752941176470588 0.752941176470588 0.752941176470588 1"/>
      </material>
    </visual>
    <collision>
      <origin rpy="0 0 0" xyz="0 0 0.01"/>
      <geometry>
        <sphere radius="0.02"/>
      </geometry>
    </collision>
    <inertial>
      <mass value="0.06"/>
      <inertia ixx="9.600000000000001e-06" ixy="0.0" ixz="0.0" iyy="9.600000000000001e-06" iyz="0.0" izz="9.600000000000001e-06"/>
    </inertial>
  </link>
  <joint name="LF_foot_fixed" type="fixed">
    <origin rpy="0 0 0" xyz="-0.001 0 -0.165"/>
    <parent link="LF_calf"/>
    <child link="LF_FOOT"/>
  </joint>
  <link name="RF_hip">
    <inertial>
      <origin rpy="0 0 0" xyz="-3.06E-03 15.19E-03 -0.23E-03"/>
      <mass value="0.31877"/>
      <inertia ixx="150729.95E-09" ixy="-14678.35E-09" ixz="199.51E-09" iyy="169042.16E-09" iyz="1285.75E-09" izz="175802.90E-09"/>
    </inertial>
    <visual>
      <origin rpy="0 0 0" xyz="0 0 0"/>
      <geometry>
        <mesh filename="package://CatModel2_description/meshes/RF_hip.STL"/>
      </geometry>
      <material name="">
        <color rgba="0.752941176470588 0.752941176470588 0.752941176470588 1"/>
      </material>
    </visual>
    <!-- <collision>
      <origin rpy="1.5707963267948966 0 0" xyz="0 0.01 0"/>
      <geometry>
        <cylinder length="0.07" radius="0.028"/>
      </geometry>
    </collision> -->
  </link>
  <joint name="RF_HAA" type="revolute">
    <origin rpy="0 0 0" xyz="0.215 -0.0650000000000001 0"/>
    <parent link="chest"/>
    <child link="RF_hip"/>
    <axis xyz="1 0 0"/>
    <limit effort="33.5" lower="-0.785" upper="0.785" velocity="18"/>
  </joint>
  <link name="RF_thigh">
    <inertial>
      <origin rpy="0 0 0" xyz="0.02E-03 23.50E-03 -19.36E-03"/>
      <mass value="0.57287"/>
      <inertia ixx="1472878.77E-09" ixy="197.96E-09" ixz="-237.91E-09" iyy="1312622.06E-09" iyz="-260046.65E-09" izz="443726.89E-09"/>
    </inertial>
    <visual>
      <origin rpy="0 0 0" xyz="0 0 0"/>
      <geometry>
        <mesh filename="package://CatModel2_description/meshes/RF_thigh.STL"/>
      </geometry>
      <material name="">
        <color rgba="0.752941176470588 0.752941176470588 0.752941176470588 1"/>
      </material>
    </visual>
    <!-- <collision>
      <origin rpy="0 1.5707963267948966 0" xyz="0 0 -0.07"/>
      <geometry>
        <box size="0.18 0.025 0.03"/>
      </geometry>
    </collision>
    <collision>
      <origin rpy="1.5707963267948966 0 0" xyz="0 0.015 0"/>
      <geometry>
        <cylinder length="0.053" radius="0.028"/>
      </geometry>
    </collision> -->
  </link>
  <joint name="RF_HFE" type="revolute">
    <origin rpy="0 0 0" xyz="0 -0.072 0"/>
    <parent link="RF_hip"/>
    <child link="RF_thigh"/>
    <axis xyz="0 1 0"/>
    <limit effort="33.5" lower="-1.05" upper="3.14" velocity="18"/>
  </joint>
  <link name="RF_calf">
    <inertial>
      <origin rpy="0 0 0" xyz="0.0 0.0 -65.28E-03"/>
      <mass value="0.09192"/>
      <inertia ixx="414588.70E-09" ixy="0.00" ixz="0.00E-09" iyy="418880.65E-09" iyz="-18.08E-09" izz="10670.32E-09"/>
    </inertial>
    <visual>
      <origin rpy="0 0 0" xyz="0 0 0"/>
      <geometry>
        <mesh filename="package://CatModel2_description/meshes/RF_calf.STL"/>
      </geometry>
      <material name="">
        <color rgba="0.752941176470588 0.752941176470588 0.752941176470588 1"/>
      </material>
    </visual>
    <collision>
      <origin rpy="0 1.5707963267948966 0" xyz="0.0 0 -0.05"/>
      <geometry>
        <box size="0.14 0.018 0.025"/>
      </geometry>
    </collision>
  </link>
  <joint name="RF_KFE" type="revolute">
    <origin rpy="0 0 0" xyz="0 0 -0.164"/>
    <parent link="RF_thigh"/>
    <child link="RF_calf"/>
    <axis xyz="0 1 0"/>
    <limit effort="33.5" lower="-2.70" upper="-0.92" velocity="18"/>
  </joint>
  <link name="RF_FOOT">
    <visual>
      <origin rpy="0 0 0" xyz="0 0 0"/>
      <geometry>
        <sphere radius="0.01"/>
      </geometry>
      <material name="">
        <color rgba="0.752941176470588 0.752941176470588 0.752941176470588 1"/>
      </material>
    </visual>
    <collision>
      <origin rpy="0 0 0" xyz="0 0 0.01"/>
      <geometry>
        <sphere radius="0.02"/>
      </geometry>
    </collision>
    <inertial>
      <mass value="0.06"/>
      <inertia ixx="9.600000000000001e-06" ixy="0.0" ixz="0.0" iyy="9.600000000000001e-06" iyz="0.0" izz="9.600000000000001e-06"/>
    </inertial>
  </link>
  <joint name="RF_foot_fixed" type="fixed">
    <origin rpy="0 0 0" xyz="-0.001 0 -0.165"/>
    <parent link="RF_calf"/>
    <child link="RF_FOOT"/>
  </joint>

    <link name="base">
    <inertial>
      <origin rpy="0 0 0" xyz="-110.92E-03 0.01E-03 -0.04E-03"/>
      <mass value="2.09468"/>
      <inertia ixx="8220668.86E-09" ixy="102.56E-09" ixz="-7414.23E-09" iyy="7271012.52E-09" iyz="-34.10E-09" izz="12352941.58E-09"/>
    </inertial>
    <visual>
      <origin rpy="0 0 0" xyz="0 0 0"/>
      <geometry>
        <mesh filename="package://CatModel2_description/meshes/base.STL"/>
      </geometry>
      <material name="">
        <color rgba="0.752941176470588 0.752941176470588 0.752941176470588 1"/>
      </material>
    </visual>
    <collision>
      <origin rpy="0 0 0" xyz="-0.12 0 0"/>
      <geometry>
        <box size="0.128 0.195 0.148"/>
      </geometry>
    </collision>
  </link>

  <joint name="Chest_joint" type="revolute">
    <origin rpy="0 0 0" xyz="0 0 0"/>
    <parent link="cross"/>
    <child link="base"/>
    <axis xyz="0 -1 0"/>
    <!-- <dynamics damping="0.1" friction="0.1"/> -->
    <limit effort="100" lower="-0.75" upper="0.75" velocity="18"/>
  </joint>
  
  <link name="LH_hip">
    <inertial>
      <origin rpy="0 0 0" xyz="-3.06E-03 -15.19E-03 0.23E-03"/>
      <mass value="0.31877"/>
      <inertia ixx="150729.95E-09" ixy="14678.35E-09" ixz="-199.51E-09" iyy="169042.16E-09" iyz="1282.75E-09" izz="175802.90E-09"/>
    </inertial>
    <visual>
      <origin rpy="0 0 0" xyz="0 0 0"/>
      <geometry>
        <mesh filename="package://CatModel2_description/meshes/LH_hip.STL"/>
      </geometry>
      <material name="">
        <color rgba="0.752941176470588 0.752941176470588 0.752941176470588 1"/>
      </material>
    </visual>
    <!-- <collision>
      <origin rpy="1.5707963267948966 0 0" xyz="0 -0.01 0"/>
      <geometry>
        <cylinder length="0.07" radius="0.028"/>
      </geometry>
    </collision> -->
  </link>
  <joint name="LH_HAA" type="revolute">
    <origin rpy="0 0 0" xyz="-0.215 0.0650000000000001 0"/>
    <parent link="base"/>
    <child link="LH_hip"/>
    <axis xyz="1 0 0"/>
    <limit effort="33.5" lower="-0.785" upper="0.785" velocity="18"/>
  </joint>
  <link name="LH_thigh">
    <inertial>
      <origin rpy="0 0 0" xyz="-0.02E-03 -23.50E-03 -19.36E-03"/>
      <mass value="0.57287"/>
      <!-- <inertia ixx="1472878.77E-09" ixy="197.96E-09" ixz="-237.97E-09" iyy="1312622.06E-09" iyz="-260046.65E-09" izz="443726.89E-09"/> -->
      <inertia ixx="1472878.77E-09" ixy="197.96E-09" ixz="237.97E-09" iyy="1312622.06E-09" iyz="260046.65E-09" izz="443726.89E-09"/>
    </inertial>
    <visual>
      <origin rpy="0 0 0" xyz="0 0 0"/>
      <geometry>
        <mesh filename="package://CatModel2_description/meshes/LH_thigh.STL"/>
      </geometry>
      <material name="">
        <color rgba="0.752941176470588 0.752941176470588 0.752941176470588 1"/>
      </material>
    </visual>
    <!-- <collision>
      <origin rpy="0 1.5707963267948966 0" xyz="0 0 -0.07"/>
      <geometry>
        <box size="0.18 0.025 0.03"/>
      </geometry>
    </collision>
    <collision>
      <origin rpy="1.5707963267948966 0 0" xyz="0 -0.015 0"/>
      <geometry>
        <cylinder length="0.053" radius="0.028"/>
      </geometry>
    </collision> -->
  </link>
  <joint name="LH_HFE" type="revolute">
    <origin rpy="0 0 0" xyz="0 0.072 0"/>
    <parent link="LH_hip"/>
    <child link="LH_thigh"/>
    <axis xyz="0 1 0"/>
    <limit effort="33.5" lower="-1.05" upper="3.14" velocity="18"/>
  </joint>
  <link name="LH_calf">
    <inertial>
      <origin rpy="0 0 0" xyz="0.0 0.0 -65.28E-03"/>
      <mass value="0.09192"/>
      <inertia ixx="414588.70E-09" ixy="0.00" ixz="0.00" iyy="418880.65E-09" iyz="-18.08E-09" izz="10670.32E-09"/>
    </inertial>
    <visual>
      <origin rpy="0 0 0" xyz="0 0 0"/>
      <geometry>
        <mesh filename="package://CatModel2_description/meshes/LH_calf.STL"/>
      </geometry>
      <material name="">
        <color rgba="0.752941176470588 0.752941176470588 0.752941176470588 1"/>
      </material>
    </visual>
    <collision>
      <origin rpy="0 1.5707963267948966 0" xyz="0.0 0 -0.05"/>
      <geometry>
        <box size="0.14 0.018 0.025"/>
      </geometry>
    </collision>
  </link>
  <joint name="LH_KFE" type="revolute">
    <origin rpy="0 0 0" xyz="0 0 -0.164"/>
    <parent link="LH_thigh"/>
    <child link="LH_calf"/>
    <axis xyz="0 1 0"/>
    <limit effort="33.5" lower="-2.70" upper="-0.92" velocity="18"/>
  </joint>
  <link name="LH_FOOT">
    <visual>
      <origin rpy="0 0 0" xyz="0 0 0"/>
      <geometry>
        <sphere radius="0.01"/>
      </geometry>
      <material name="">
        <color rgba="0.752941176470588 0.752941176470588 0.752941176470588 1"/>
      </material>
    </visual>
    <collision>
      <origin rpy="0 0 0" xyz="0 0 0.01"/>
      <geometry>
        <sphere radius="0.02"/>
      </geometry>
    </collision>
    <inertial>
      <mass value="0.06"/>
      <inertia ixx="9.600000000000001e-06" ixy="0.0" ixz="0.0" iyy="9.600000000000001e-06" iyz="0.0" izz="9.600000000000001e-06"/>
    </inertial>
  </link>
  <joint name="LH_foot_fixed" type="fixed">
    <origin rpy="0 0 0" xyz="-0.001 0 -0.165"/>
    <parent link="LH_calf"/>
    <child link="LH_FOOT"/>
  </joint>
  <link name="RH_hip">
    <inertial>
      <origin rpy="0 0 0" xyz="3.06E-03 15.19E-03 0.23E-03"/>
      <mass value="0.31877"/>
      <inertia ixx="150729.95E-09" ixy="14678.35E-09" ixz="199.51E-09" iyy="169042.16E-09" iyz="-1282.75E-09" izz="175802.90E-09"/>
    </inertial>
    <visual>
      <origin rpy="0 0 0" xyz="0 0 0"/>
      <geometry>
        <mesh filename="package://CatModel2_description/meshes/RH_hip.STL"/>
      </geometry>
      <material name="">
        <color rgba="0.752941176470588 0.752941176470588 0.752941176470588 1"/>
      </material>
    </visual>
    <!-- <collision>
      <origin rpy="1.5707963267948966 0 0" xyz="0 0.01 0"/>
      <geometry>
        <cylinder length="0.07" radius="0.028"/>
      </geometry>
    </collision> -->
  </link>
  <joint name="RH_HAA" type="revolute">
    <origin rpy="0 0 0" xyz="-0.215 -0.065 0"/>
    <parent link="base"/>
    <child link="RH_hip"/>
    <axis xyz="1 0 0"/>
    <limit effort="33.5" lower="-0.785" upper="0.785" velocity="18"/>
  </joint>
  <link name="RH_thigh">
    <inertial>
      <origin rpy="0 0 0" xyz="0.02E-03 23.50E-03 -19.36E-03"/>
      <mass value="0.57287"/>
      <inertia ixx="1472878.77E-09" ixy="197.96E-09" ixz="-237.97E-09" iyy="1312622.06e-09" iyz="-260046.65E-09" izz="443726.89E-09"/>
    </inertial>
    <visual>
      <origin rpy="0 0 0" xyz="0 0 0"/>
      <geometry>
        <mesh filename="package://CatModel2_description/meshes/RH_thigh.STL"/>
      </geometry>
      <material name="">
        <color rgba="0.752941176470588 0.752941176470588 0.752941176470588 1"/>
      </material>
    </visual>
    <!-- <collision>
      <origin rpy="0 1.5707963267948966 0" xyz="0 0 -0.07"/>
      <geometry>
        <box size="0.18 0.025 0.03"/>
      </geometry>
    </collision>
    <collision>
      <origin rpy="1.5707963267948966 0 0" xyz="0 0.015 0"/>
      <geometry>
        <cylinder length="0.053" radius="0.028"/>
      </geometry>
    </collision> -->
  </link>
  <joint name="RH_HFE" type="revolute">
    <origin rpy="0 0 0" xyz="0 -0.072 0"/>
    <parent link="RH_hip"/>
    <child link="RH_thigh"/>
    <axis xyz="0 1 0"/>
    <limit effort="33.5" lower="-1.05" upper="3.14" velocity="18"/>
  </joint>
  <link name="RH_calf">
    <inertial>
      <origin rpy="0 0 0" xyz="0.0 0.0 -65.28E-03"/>
      <mass value="0.09192"/>
      <inertia ixx="414588.70E-09" ixy="0.00" ixz="0.00" iyy="418880.65E-09" iyz="-18.08E-09" izz="10670.32E-09"/>
    </inertial>
    <visual>
      <origin rpy="0 0 0" xyz="0 0 0"/>
      <geometry>
        <mesh filename="package://CatModel2_description/meshes/RH_calf.STL"/>
      </geometry>
      <material name="">
        <color rgba="0.752941176470588 0.752941176470588 0.752941176470588 1"/>
      </material>
    </visual>
    <collision>
      <origin rpy="0 1.5707963267948966 0" xyz="0.0 0 -0.05"/>
      <geometry>
        <box size="0.14 0.018 0.025"/>
      </geometry>
    </collision>
  </link>
  <joint name="RH_KFE" type="revolute">
    <origin rpy="0 0 0" xyz="0 0 -0.164"/>
    <parent link="RH_thigh"/>
    <child link="RH_calf"/>
    <axis xyz="0 1 0"/>
    <limit effort="33.5" lower="-2.70" upper="-0.92" velocity="18"/>
  </joint>
  <link name="RH_FOOT">
    <visual>
      <origin rpy="0 0 0" xyz="0 0 0"/>
      <geometry>
        <sphere radius="0.01"/>
      </geometry>
      <material name="">
        <color rgba="0.752941176470588 0.752941176470588 0.752941176470588 1"/>
      </material>
    </visual>
    <collision>
      <origin rpy="0 0 0" xyz="0 0 0.01"/>
      <geometry>
        <sphere radius="0.02"/>
      </geometry>
    </collision>
    <inertial>
      <mass value="0.06"/>
      <inertia ixx="9.600000000000001e-06" ixy="0.0" ixz="0.0" iyy="9.600000000000001e-06" iyz="0.0" izz="9.600000000000001e-06"/>
    </inertial>
  </link>
  <joint name="RH_foot_fixed" type="fixed">
    <origin rpy="0 0 0" xyz="-0.001 0 -0.165"/>
    <parent link="RH_calf"/>
    <child link="RH_FOOT"/>
  </joint>

</robot>

