<mujoco model="CatModel2_v1">
  <compiler angle="radian" meshdir="assets" texturedir="assets" autolimits="true"/>

  <option cone="elliptic" impratio="100"/>
  
  <default>
    <default class="CatModel2_v1">
      <geom friction="0.4" margin="0.001" condim="1"/>
      <joint axis="0 1 0" damping="0.1" armature="0.01" frictionloss="0.2"/>
      <motor ctrlrange="-23.7 23.7"/>
      <default class="HAA">
        <joint axis="1 0 0" range="-0.785 0.785"/>
      </default>
      <default class="HFE">
        <joint range="-1.05 3.14"/>
      </default>
      <default class="KFE">
        <joint range="-2.70 -0.92"/>
        <!-- <motor ctrlrange="-45.43 45.43"/> -->
      </default>
      <default class="visual">
        <geom type="mesh" contype="0" conaffinity="0" group="2"/>
      </default>
      <default class="collision">
        <geom group="3" type="capsule"/>
        <default class="foot">
          <geom type="sphere" size="0.02" pos="-0.001 0 -0.155" priority="1" solimp="0.015 1 0.02" condim="6"
            friction="0.8 0.02 0.01"/>
        </default>
      </default>
    </default>
  </default>

  <asset>
    <material name="transparent" rgba="1 1 1 0.01" />
    <mesh name="cross" file="cross.STL"/>
    <mesh name="chest" file="chest.STL"/>
    <mesh name="LF_hip" file="LF_hip.STL"/>
    <mesh name="LF_thigh" file="LF_thigh.STL"/>
    <mesh name="LF_calf" file="LF_calf.STL"/>
    <mesh name="RF_hip" file="RF_hip.STL"/>
    <mesh name="RF_thigh" file="RF_thigh.STL"/>
    <mesh name="RF_calf" file="RF_calf.STL"/>
    <mesh name="base" file="base.STL"/>
    <mesh name="LH_hip" file="LH_hip.STL"/>
    <mesh name="LH_thigh" file="LH_thigh.STL"/>
    <mesh name="LH_calf" file="LH_calf.STL"/>
    <mesh name="RH_hip" file="RH_hip.STL"/>
    <mesh name="RH_thigh" file="RH_thigh.STL"/>
    <mesh name="RH_calf" file="RH_calf.STL"/>
  </asset>

  <worldbody>
    <body name="cross" pos="0 0 0.3" childclass = "CatModel2_v1">
      <inertial pos="0 0 0" mass="0.10303" diaginertia="0.00013 0.000065 0.000065"/>
      <freejoint />
      <geom mesh="cross" class="visual"/>
      <geom size="0.0055 0.015 0.065" type="box" class="collision"/>
      <geom size="0.0055 0.015 0.065" quat="0.707107 0.707107 0 0" type="box" class="collision"/>
      <site name="imu" pos="0 0 0.04232" />
      <body name="chest">
        <inertial pos="0.11071 8e-05 -4e-05" quat="0.00212895 0.707996 -0.00232425 0.706209" mass="2.10511" diaginertia="0.0111593 0.00851122 0.00822238"/>
        <joint name="Base_joint" pos="0 0 0" axis="0 0 1" range="-0.75 0.75" actuatorfrcrange="-100 100"/>
        <geom mesh="chest" class="visual"/>
        <geom size="0.064 0.0975 0.074" pos="0.12 0 0" type="box" class="collision"/>
        <body name="LF_hip" pos="0.215 0.065 0">
          <inertial pos="-0.00306 -0.01519 0.00023" quat="0.185832 0.50867 0.498 0.677287" mass="0.31877" diaginertia="0.000177897 0.000175098 0.00014258"/>
          <joint name="LF_HAA" class = "HAA"/>
          <geom  mesh="LF_hip" class="visual"/>
          <body name="LF_thigh" pos="0 0.072 0">
            <inertial pos="-2e-05 -0.0235 -0.01936" quat="0.990922 0.134433 -0.000272823 0.00141436" mass="0.57287" diaginertia="0.00147288 0.0013845 0.000371846"/>
            <joint name="LF_HFE" class = "HFE"/>
            <geom  mesh="LF_thigh" class = "visual"/>
            <body name="LF_calf" pos="0 0 -0.164">
              <inertial pos="-0.000394945 0 -0.104664" quat="0.707098 0.00168163 0.00166497 0.707112" mass="0.15192" diaginertia="0.00078952 0.000785209 2.02895e-05"/>
              <joint name="LF_KFE" class = "KFE"/>
              <geom  mesh="LF_calf" class = "visual"/>
              <geom size="0.07 0.009 0.0125" pos="0 0 -0.05" quat="0.707107 0 0.707107 0" type="box" class = "collision"/>
              <geom class="foot"/>
              <site name="LF_touch" pos="0 0 -0.155" size="0.022" material="transparent"/>
              <!-- <geom size="0.02" pos="-0.001 0 -0.155" class = "collision"/> -->
            </body>
          </body>
        </body>
        <body name="RF_hip" pos="0.215 -0.065 0">
          <inertial pos="-0.00306 0.01519 -0.00023" quat="0.196799 0.502194 0.509723 0.670264" mass="0.31877" diaginertia="0.000177737 0.000175271 0.000142567"/>
          <joint name="RF_HAA" class = "HAA"/>
          <geom mesh="RF_hip" class = "visual"/>
          <body name="RF_thigh" pos="0 -0.072 0">
            <inertial pos="2e-05 0.0235 -0.01936" quat="0.990922 -0.134433 0.000272785 0.00141428" mass="0.57287" diaginertia="0.00147288 0.0013845 0.000371846"/>
            <joint name="RF_HFE" class = "HFE"/>
            <geom mesh="RF_thigh" class = "visual"/>
            <body name="RF_calf" pos="0 0 -0.164">
              <inertial pos="-0.000394945 0 -0.104664" quat="0.707112 0.00166497 0.00168163 0.707098" mass="0.15192" diaginertia="0.00078952 0.000785209 2.02895e-05"/>
              <joint name="RF_KFE" class = "KFE"/>
              <geom mesh="RF_calf" class = "visual"/>
              <geom size="0.07 0.009 0.0125" pos="0 0 -0.05" quat="0.707107 0 0.707107 0" type="box" class = "collision"/>
              <!-- <geom size="0.01" pos="-0.001 0 -0.165" contype="0" conaffinity="0" group="1" density="0" rgba="0.752941 0.752941 0.752941 1"/>
              <geom size="0.02" pos="-0.001 0 -0.155" rgba="0.752941 0.752941 0.752941 1"/> -->
              <geom class="foot"/>
              <site name="RF_touch" pos="0 0 -0.155" size="0.022" material="transparent"/>
            </body>
          </body>
        </body>
      </body>
      <body name="base">
        <inertial pos="-0.11092 1e-05 -4e-05" quat="0.499523 0.49958 -0.500423 0.500474" mass="2.09468" diaginertia="0.012353 0.00822066 0.00727101"/>
        <joint name="Chest_joint" pos="0 0 0" axis="0 -1 0" range="-0.75 0.75" actuatorfrcrange="-100 100"/>
        <geom mesh="base" class = "visual"/>
        <geom size="0.064 0.0975 0.074" pos="-0.12 0 0" type="box" class = "collision"/>
        <body name="LH_hip" pos="-0.215 0.065 0">
          <inertial pos="-0.00306 -0.01519 0.00023" quat="0.509862 0.67022 0.197006 0.502031" mass="0.31877" diaginertia="0.000177735 0.000175273 0.000142567"/>
          <joint name="LH_HAA" class = "HAA"/>
          <geom type="mesh" mesh="LH_hip" class = "visual"/>
          <body name="LH_thigh" pos="0 0.072 0">
            <inertial pos="-2e-05 -0.0235 -0.01936" quat="0.990922 0.134433 -0.000272823 0.00141436" mass="0.57287" diaginertia="0.00147288 0.0013845 0.000371846"/>
            <joint name="LH_HFE" class = "HFE"/>
            <geom type="mesh" mesh="LH_thigh" class = "visual"/>
            <body name="LH_calf" pos="0 0 -0.164">
              <inertial pos="-0.000394945 0 -0.104664" quat="0.707112 0.00166497 0.00168163 0.707098" mass="0.15192" diaginertia="0.00078952 0.000785209 2.02895e-05"/>
              <joint name="LH_KFE" class = "KFE"/>
              <geom type="mesh" mesh="LH_calf" class = "visual"/>
              <geom size="0.07 0.009 0.0125" pos="0 0 -0.05" quat="0.707107 0 0.707107 0" type="box" class = "collision"/>
              <!-- <geom size="0.01" pos="-0.001 0 -0.165" contype="0" conaffinity="0" group="1" density="0" rgba="0.752941 0.752941 0.752941 1"/>
              <geom size="0.02" pos="-0.001 0 -0.155" rgba="0.752941 0.752941 0.752941 1"/> -->
              <geom class="foot"/>
              <site name="LH_touch" pos="0 0 -0.155" size="0.022" material="transparent"/>
            </body>
          </body>
        </body>
        <body name="RH_hip" pos="-0.215 -0.065 0">
          <inertial pos="0.00306 0.01519 0.00023" quat="0.67022 0.509862 0.502031 0.197006" mass="0.31877" diaginertia="0.000177735 0.000175273 0.000142567"/>
          <joint name="RH_HAA" class = "HAA"/>
          <geom type="mesh" mesh="RH_hip" class = "visual"/>
          <body name="RH_thigh" pos="0 -0.072 0">
            <inertial pos="2e-05 0.0235 -0.01936" quat="0.990922 -0.134433 0.000272823 0.00141436" mass="0.57287" diaginertia="0.00147288 0.0013845 0.000371846"/>
            <joint name="RH_HFE" class = "HFE"/>
            <geom type="mesh" mesh="RH_thigh" class = "visual"/>
            <body name="RH_calf" pos="0 0 -0.164">
              <inertial pos="-0.000394945 0 -0.104664" quat="0.707112 0.00166497 0.00168163 0.707098" mass="0.15192" diaginertia="0.00078952 0.000785209 2.02895e-05"/>
              <joint name="RH_KFE" class = "KFE"/>
              <geom type="mesh" mesh="RH_calf" class = "visual"/>
              <geom size="0.07 0.009 0.0125" pos="0 0 -0.05" quat="0.707107 0 0.707107 0" type="box" class = "collision"/>
              <!-- <geom size="0.01" pos="-0.001 0 -0.165" contype="0" conaffinity="0" group="1" density="0" rgba="0.752941 0.752941 0.752941 1"/>
              <geom size="0.02" pos="-0.001 0 -0.155" rgba="0.752941 0.752941 0.752941 1"/> -->
              <geom class="foot"/>
              <site name="RH_touch" pos="0 0 -0.155" size="0.022" material="transparent"/>
            </body>
          </body>
        </body>
      </body>  
    </body>
  </worldbody>

  <actuator>
    <motor name="Base_joint_motor" joint="Base_joint" />
    <motor name="Chest_joint_motor" joint="Chest_joint" />
    <motor class="HAA" name="LF_HAA_motor" joint="LF_HAA" />
    <motor class="HFE" name="LF_HFE_motor" joint="LF_HFE" />
    <motor class="KFE" name="LF_KFE_motor" joint="LF_KFE" />
    <motor class="HAA" name="RF_HAA_motor" joint="RF_HAA" />
    <motor class="HFE" name="RF_HFE_motor" joint="RF_HFE" />
    <motor class="KFE" name="RF_KFE_motor" joint="RF_KFE" />
    <motor class="HAA" name="LH_HAA_motor" joint="LH_HAA" />
    <motor class="HFE" name="LH_HFE_motor" joint="LH_HFE" />
    <motor class="KFE" name="LH_KFE_motor" joint="LH_KFE" />
    <motor class="HAA" name="RH_HAA_motor" joint="RH_HAA" />
    <motor class="HFE" name="RH_HFE_motor" joint="RH_HFE" />
    <motor class="KFE" name="RH_KFE_motor" joint="RH_KFE" />
  </actuator>

  <sensor>
    <jointpos name="Base_joint_pos" joint="Base_joint"/>
    <jointpos name="Chest_joint_pos" joint="Chest_joint"/>
    <jointpos name="LF_HAA_pos" joint="LF_HAA"/>
    <jointpos name="LF_HFE_pos" joint="LF_HFE"/>
    <jointpos name="LF_KFE_pos" joint="LF_KFE"/>
    <jointpos name="RF_HAA_pos" joint="RF_HAA"/>
    <jointpos name="RF_HFE_pos" joint="RF_HFE"/>
    <jointpos name="RF_KFE_pos" joint="RF_KFE"/>
    <jointpos name="LH_HAA_pos" joint="LH_HAA"/>
    <jointpos name="LH_HFE_pos" joint="LH_HFE"/>
    <jointpos name="LH_KFE_pos" joint="LH_KFE"/>
    <jointpos name="RH_HAA_pos" joint="RH_HAA"/>
    <jointpos name="RH_HFE_pos" joint="RH_HFE"/>
    <jointpos name="RH_KFE_pos" joint="RH_KFE"/>

    <jointvel name="Base_joint_vel" joint="Base_joint"/>
    <jointvel name="Chest_joint_vel" joint="Chest_joint"/>
    <jointvel name="LF_HAA_vel" joint="LF_HAA"/>
    <jointvel name="LF_HFE_vel" joint="LF_HFE"/>
    <jointvel name="LF_KFE_vel" joint="LF_KFE"/>
    <jointvel name="RF_HAA_vel" joint="RF_HAA"/>
    <jointvel name="RF_HFE_vel" joint="RF_HFE"/>
    <jointvel name="RF_KFE_vel" joint="RF_KFE"/>
    <jointvel name="LH_HAA_vel" joint="LH_HAA"/>
    <jointvel name="LH_HFE_vel" joint="LH_HFE"/>
    <jointvel name="LH_KFE_vel" joint="LH_KFE"/>
    <jointvel name="RH_HAA_vel" joint="RH_HAA"/>
    <jointvel name="RH_HFE_vel" joint="RH_HFE"/>
    <jointvel name="RH_KFE_vel" joint="RH_KFE"/>



    <jointactuatorfrc name="Base_joint_torque" joint="Base_joint" noise="0.01"/>
    <jointactuatorfrc name="Chest_joint_torque" joint="Chest_joint" noise="0.01"/>
    <jointactuatorfrc name="LF_HAA_torque" joint="LF_HAA" noise="0.01"/>
    <jointactuatorfrc name="LF_HFE_torque" joint="LF_HFE" noise="0.01"/>
    <jointactuatorfrc name="LF_KFE_torque" joint="LF_KFE" noise="0.01"/>
    <jointactuatorfrc name="RF_HAA_torque" joint="RF_HAA" noise="0.01"/>
    <jointactuatorfrc name="RF_HFE_torque" joint="RF_HFE" noise="0.01"/>
    <jointactuatorfrc name="RF_KFE_torque" joint="RF_KFE" noise="0.01"/>
    <jointactuatorfrc name="LH_HAA_torque" joint="LH_HAA" noise="0.01"/>
    <jointactuatorfrc name="LH_HFE_torque" joint="LH_HFE" noise="0.01"/>
    <jointactuatorfrc name="LH_KFE_torque" joint="LH_KFE" noise="0.01"/>
    <jointactuatorfrc name="RH_HAA_torque" joint="RH_HAA" noise="0.01"/>
    <jointactuatorfrc name="RH_HFE_torque" joint="RH_HFE" noise="0.01"/>
    <jointactuatorfrc name="RH_KFE_torque" joint="RH_KFE" noise="0.01"/>

    <framequat name="imu_quat" objtype="site" objname="imu"/>
    <gyro name="imu_gyro" site="imu"/>
    <accelerometer name="imu_acc" site="imu"/>

    <framepos name="frame_pos" objtype="site" objname="imu"/>
    <framelinvel name="frame_vel" objtype="site" objname="imu"/>

    <touch name="LF_touch" site="LF_touch"/>
    <touch name="RF_touch" site="RF_touch"/>
    <touch name="LH_touch" site="LH_touch"/>
    <touch name="RH_touch" site="RH_touch"/>
  </sensor>

  <keyframe>
    <key name="home" qpos="0 0 0.15 1 0 0 0 0 0 0.4 1.2 -2.7 -0.4 1.2 -2.7 0.4 1.2 -2.7 -0.4 1.2 -2.7"
      ctrl="0 0 0 0 0 0 0 0 0 0 0 0 0 0 "/>
  </keyframe>

</mujoco>
