<mujoco model="go1">
  <compiler angle="radian" meshdir="assets/"/>

  <option cone="elliptic" impratio="100"/>

  <default>
    <default class="go1">
      <geom friction="0.4" margin="0.001" condim="1"/>
      <joint axis="0 1 0" damping="0.1" armature="0.01" frictionloss="0.2"/>
      <motor ctrlrange="-23.7 23.7"/>
      <default class="abduction">
        <joint axis="1 0 0" range="-0.863 0.863"/>
      </default>
      <default class="hip">
        <default class="front_hip">
          <joint range="-0.686 4.501"/>
        </default>
        <default class="back_hip">
          <joint range="-0.686 4.501"/>
        </default>
      </default>
      <default class="knee">
        <joint range="-2.818 -0.888"/>
        <motor ctrlrange="-35.55 35.55"/>
      </default>
      <default class="visual">
        <geom type="mesh" contype="0" conaffinity="0" group="2" material="dark"/>
      </default>
      <default class="collision">
        <geom group="3"/>
        <default class="foot">
          <geom size="0.022" pos="-0.002 0 -0.213" priority="1" condim="6"
                friction="0.4 0.02 0.01"/>
        </default>
      </default>
    </default>
  </default>

  <asset>
    <material name="metal" rgba=".6 .6 .6 1" shininess="0.5"/>
    <material name="black" rgba=".1 .1 .1 1" shininess="0.25"/>
    <material name="dark" rgba="0.4 0.4 0.4 1" shininess="0.1"/>
    <material name="transparent" rgba="1 1 1 0.01"/>

    <mesh name="trunk" file="trunk.obj" scale="0.0001 0.0001 0.0001"/>
    <mesh name="hip" file="hip.obj" scale="0.001 0.001 0.001"/>
    <mesh name="thigh_mirror" file="thigh_mirror.obj" scale="0.001 0.001 0.001"/>
    <mesh name="calf" file="calf.obj" scale="0.001 0.001 0.001"/>
    <mesh name="thigh" file="thigh.obj" scale="0.001 0.001 0.001"/>
    <mesh name="depthCamera" file="depthCamera.obj" scale="0.001 0.001 0.001"/>
    <mesh name="ultraSound" file="ultraSound.obj" scale="0.001 0.001 0.001"/>
  </asset>

  <worldbody>
    <body name="base_link" pos="0 0 0.445" childclass="go1">
      <inertial pos="0.021112 0 -0.005366" quat="-0.000543471 0.713435 -0.00173769 0.700719"
                mass="6.921"
                diaginertia="0.107027 0.0980771 0.0244531"/>
      <freejoint/>
      <geom type="mesh" mesh="trunk" class="visual" material="dark"/>
      <geom size="0.1881 0.04675 0.057" type="box" class="collision"/>
      <geom size="0.0005 0.0005 0.0005" type="box" contype="0" conaffinity="0" group="2" density="0"/>
      <geom size="0.0005 0.0005 0.0005" pos="-0.01592 -0.06659 -0.00617" type="box" contype="0" conaffinity="0"
            group="2" density="0"/>
      <geom size="0.0005 0.0005 0.0005" pos="-0.01592 -0.06659 -0.00617" type="box"/>
      <geom size="0.035 0.01" pos="0.11215 -0.04675 0" quat="0.707107 0 0.707107 0" type="cylinder" contype="0"
            conaffinity="0" group="2" density="0" rgba="0 0.8 0 1"/>
      <geom size="0.035 0.01" pos="0.11215 -0.04675 0" quat="0.707107 0 0.707107 0" type="cylinder" rgba="0 0.8 0 1"/>
      <geom size="0.035 0.01" pos="0.11215 0.04675 0" quat="0.707107 0 0.707107 0" type="cylinder" contype="0"
            conaffinity="0" group="2" density="0" rgba="0 0.8 0 1"/>
      <geom size="0.035 0.01" pos="0.11215 0.04675 0" quat="0.707107 0 0.707107 0" type="cylinder" rgba="0 0.8 0 1"/>
      <geom size="0.035 0.01" pos="-0.11215 -0.04675 0" quat="0.707107 0 0.707107 0" type="cylinder" contype="0"
            conaffinity="0" group="2" density="0" rgba="0 0.8 0 1"/>
      <geom size="0.035 0.01" pos="-0.11215 -0.04675 0" quat="0.707107 0 0.707107 0" type="cylinder" rgba="0 0.8 0 1"/>
      <geom size="0.035 0.01" pos="-0.11215 0.04675 0" quat="0.707107 0 0.707107 0" type="cylinder" contype="0"
            conaffinity="0" group="2" density="0" rgba="0 0.8 0 1"/>
      <geom size="0.035 0.01" pos="-0.11215 0.04675 0" quat="0.707107 0 0.707107 0" type="cylinder" rgba="0 0.8 0 1"/>
      <geom size="0.0005 0.0005 0.0005" pos="0.2785 0.0125 0.0167" quat="0 1 0 0" type="box"/>
      <geom pos="0.2785 0.0125 0.0167" quat="0 1 0 0" type="mesh" contype="0" conaffinity="0" group="2" density="0"
            mesh="depthCamera"/>
      <geom size="0.0005 0.0005 0.0005" pos="0.2522 0.0125 -0.0436" quat="0 0.707107 0 -0.707107" type="box"/>
      <geom pos="0.2522 0.0125 -0.0436" quat="0 0.707107 0 -0.707107" type="mesh" contype="0" conaffinity="0" group="2"
            density="0" mesh="depthCamera"/>
      <geom size="0.0005 0.0005 0.0005" pos="-0.066 0.082 -0.0176" quat="0.0922962 0.701057 0.701057 -0.0922962"
            type="box"/>
      <geom pos="-0.066 0.082 -0.0176" quat="0.0922962 0.701057 0.701057 -0.0922962" type="mesh" contype="0"
            conaffinity="0" group="2" density="0" mesh="depthCamera"/>
      <geom size="0.0005 0.0005 0.0005" pos="-0.041 -0.082 -0.0176" quat="-0.0922962 0.701057 -0.701057 -0.0922962"
            type="box"/>
      <geom pos="-0.041 -0.082 -0.0176" quat="-0.0922962 0.701057 -0.701057 -0.0922962" type="mesh" contype="0"
            conaffinity="0" group="2" density="0" mesh="depthCamera"/>
      <geom size="0.0005 0.0005 0.0005" pos="-0.0825 0.0125 -0.04365" quat="0 0.707107 0 -0.707107" type="box"/>
      <geom pos="-0.0825 0.0125 -0.04365" quat="0 0.707107 0 -0.707107" type="mesh" contype="0" conaffinity="0"
            group="2" density="0" mesh="depthCamera"/>
      <geom size="0.0005 0.0005 0.0005" pos="-0.0535 0.0826 0.00868" quat="0.701057 -0.0922962 0.0922962 0.701057"
            type="box"/>
      <geom pos="-0.0535 0.0826 0.00868" quat="0.701057 -0.0922962 0.0922962 0.701057" type="mesh" contype="0"
            conaffinity="0" group="2" density="0" rgba="0 0 0 1" mesh="ultraSound"/>
      <geom size="0.0005 0.0005 0.0005" pos="-0.0535 -0.0826 0.00868" quat="0.701057 0.0922962 0.0922962 -0.701057"
            type="box"/>
      <geom pos="-0.0535 -0.0826 0.00868" quat="0.701057 0.0922962 0.0922962 -0.701057" type="mesh" contype="0"
            conaffinity="0" group="2" density="0" rgba="0 0 0 1" mesh="ultraSound"/>
      <geom size="0.0005 0.0005 0.0005" pos="0.2747 0 -0.0088" type="box"/>
      <geom pos="0.2747 0 -0.0088" quat="1 0 0 0" type="mesh" contype="0" conaffinity="0" group="2" density="0"
            rgba="0 0 0 1" mesh="ultraSound"/>
      <site name="imu" pos="-0.02557 0 0.04232"/>

      <body name="FL_hip" pos="0.1881 0.04675 0">
        <inertial pos="-0.0049166 -0.00762615 -8.865e-05" quat="0.482891 0.495027 0.514169 0.507341" mass="0.68"
                  diaginertia="0.000734064 0.000468438 0.000398719"/>
        <joint name="FL_hip_joint" class="abduction"/>
        <geom type="mesh" class="visual" material="metal" mesh="hip"/>
        <geom size="0.046 0.02" pos="0 0.08 0" quat="0.707107 0.707107 0 0" type="cylinder" class="collision"/>
        <geom size="0.035 0.01" pos="0 -0.00015 0" quat="0.707107 0.707107 0 0" type="cylinder" contype="0"
              conaffinity="0" group="2" density="0" rgba="0 0.8 0 1"/>
        <geom size="0.035 0.01" pos="0 -0.00015 0" quat="0.707107 0.707107 0 0" type="cylinder" rgba="0 0.8 0 1"/>
        <body name="FL_thigh" pos="0 0.08 0">
          <inertial pos="-0.00304722 -0.019315 -0.0305004" quat="0.753383 0.0775126 -0.0272313 0.65243" mass="1.009"
                    diaginertia="0.00478717 0.00460903 0.000709268"/>
          <joint name="FL_thigh_joint" class="front_hip"/>
          <geom type="mesh" class="visual" material="metal" mesh="thigh"/>
          <geom size="0.1065 0.01225 0.017" pos="0 0 -0.1065" quat="0.707107 0 0.707107 0" type="box"
                class="collision"/>
          <geom size="0.035 0.01" pos="0 -0.03235 0" quat="0.707107 0.707107 0 0" type="cylinder" contype="0"
                conaffinity="0" group="2" density="0" rgba="0 0.8 0 1"/>
          <geom size="0.035 0.01" pos="0 -0.03235 0" quat="0.707107 0.707107 0 0" type="cylinder" rgba="0 0.8 0 1"/>
          <body name="FL_calf" pos="0 0 -0.213">
            <inertial pos="0.00429862 0.000976676 -0.146197" quat="0.691246 0.00357467 0.00511118 0.722592"
                      mass="0.195862" diaginertia="0.00149767 0.00148468 3.58427e-05"/>
            <joint name="FL_calf_joint" class="knee"/>
            <geom class="visual" material="dark" type="mesh" mesh="calf"/>
            <geom size="0.1065 0.008 0.008" pos="0 0 -0.1065" quat="0.707107 0 0.707107 0" type="box"
                  class="collision"/>
            <geom size="0.01" pos="0 0 -0.213" contype="0" conaffinity="0" group="2" density="0"/>
            <geom size="0.02" pos="0 0 -0.213"/>
            <site name="FL_touch" pos="0 0 -0.213" size="0.027" material="transparent"/>
          </body>
        </body>
      </body>
      <body name="FR_hip" pos="0.1881 -0.04675 0">
        <inertial pos="-0.0049166 0.00762615 -8.865e-05" quat="0.507341 0.514169 0.495027 0.482891"
                  mass="0.68"
                  diaginertia="0.000734064 0.000468438 0.000398719"/>
        <joint name="FR_hip_joint" class="abduction"/>
        <geom quat="0 1 0 0" type="mesh" class="visual" material="metal" mesh="hip"/>
        <geom size="0.046 0.02" pos="0 -0.08 0" quat="0.707107 0.707107 0 0" type="cylinder" class="collision"/>
        <geom size="0.035 0.01" pos="0 0.00015 0" quat="0.707107 0.707107 0 0" type="cylinder" contype="0"
              conaffinity="0" group="2" density="0" rgba="0 0.8 0 1"/>
        <geom size="0.035 0.01" pos="0 0.00015 0" quat="0.707107 0.707107 0 0" type="cylinder" rgba="0 0.8 0 1"/>
        <body name="FR_thigh" pos="0 -0.08 0">
          <inertial pos="-0.00304722 0.019315 -0.0305004" quat="0.65243 -0.0272313 0.0775126 0.753383" mass="1.009"
                    diaginertia="0.00478717 0.00460903 0.000709268"/>
          <joint name="FR_thigh_joint" class="front_hip"/>
          <geom type="mesh" class="visual" material="metal" mesh="thigh_mirror"/>
          <geom size="0.1065 0.01225 0.017" pos="0 0 -0.1065" quat="0.707107 0 0.707107 0" type="box"
                class="collision"/>
          <geom size="0.035 0.01" pos="0 0.03235 0" quat="0.707107 0.707107 0 0" type="cylinder" contype="0"
                conaffinity="0" group="2" density="0" rgba="0 0.8 0 1"/>
          <geom size="0.035 0.01" pos="0 0.03235 0" quat="0.707107 0.707107 0 0" type="cylinder" rgba="0 0.8 0 1"/>
          <body name="FR_calf" pos="0 0 -0.213">
            <inertial pos="0.00429862 0.000976676 -0.146197" quat="0.691246 0.00357467 0.00511118 0.722592"
                      mass="0.195862" diaginertia="0.00149767 0.00148468 3.58427e-05"/>
            <joint name="FR_calf_joint" class="knee"/>
            <geom type="mesh" class="visual" material="dark" mesh="calf"/>
            <geom size="0.1065 0.008 0.008" pos="0 0 -0.1065" quat="0.707107 0 0.707107 0" type="box"
                  class="collision"/>
            <geom size="0.01" pos="0 0 -0.213" contype="0" conaffinity="0" group="2" density="0"/>
            <geom size="0.02" pos="0 0 -0.213"/>
            <site name="FR_touch" pos="0 0 -0.213" size="0.027" material="transparent"/>
          </body>
        </body>
      </body>
      <body name="RL_hip" pos="-0.1881 0.04675 0">
        <inertial pos="0.0049166 -0.00762615 -8.865e-05" quat="0.514169 0.507341 0.482891 0.495027" mass="0.68"
                  diaginertia="0.000734064 0.000468438 0.000398719"/>
        <joint name="RL_hip_joint" class="abduction"/>
        <geom quat="0 0 1 0" class="visual" material="metal" mesh="hip"/>
        <geom size="0.046 0.02" pos="0 0.08 0" quat="0.707107 0.707107 0 0" type="cylinder" class="collision"/>
        <geom size="0.035 0.01" pos="0 -0.00015 0" quat="0.707107 0.707107 0 0" type="cylinder" contype="0"
              conaffinity="0" group="2" density="0" rgba="0 0.8 0 1"/>
        <geom size="0.035 0.01" pos="0 -0.00015 0" quat="0.707107 0.707107 0 0" type="cylinder" rgba="0 0.8 0 1"/>
        <body name="RL_thigh" pos="0 0.08 0">
          <inertial pos="-0.00304722 -0.019315 -0.0305004" quat="0.753383 0.0775126 -0.0272313 0.65243" mass="1.009"
                    diaginertia="0.00478717 0.00460903 0.000709268"/>
          <joint name="RL_thigh_joint" class="back_hip"/>
          <geom type="mesh" class="visual" material="metal" mesh="thigh"/>
          <geom size="0.1065 0.01225 0.017" pos="0 0 -0.1065" quat="0.707107 0 0.707107 0" type="box"
                class="collision"/>
          <geom size="0.035 0.01" pos="0 -0.03235 0" quat="0.707107 0.707107 0 0" type="cylinder" contype="0"
                conaffinity="0" group="2" density="0" rgba="0 0.8 0 1"/>
          <geom size="0.035 0.01" pos="0 -0.03235 0" quat="0.707107 0.707107 0 0" type="cylinder" rgba="0 0.8 0 1"/>
          <body name="RL_calf" pos="0 0 -0.213">
            <inertial pos="0.00429862 0.000976676 -0.146197" quat="0.691246 0.00357467 0.00511118 0.722592"
                      mass="0.195862" diaginertia="0.00149767 0.00148468 3.58427e-05"/>
            <joint name="RL_calf_joint" class="knee"/>
            <geom type="mesh" class="visual" material="dark" mesh="calf"/>
            <geom size="0.1065 0.008 0.008" pos="0 0 -0.1065" quat="0.707107 0 0.707107 0" type="box"
                  class="collision"/>
            <geom size="0.01" pos="0 0 -0.213" contype="0" conaffinity="0" group="2" density="0"/>
            <geom size="0.02" pos="0 0 -0.213"/>
            <site name="RL_touch" pos="0 0 -0.213" size="0.027" material="transparent"/>
          </body>
        </body>
      </body>
      <body name="RR_hip" pos="-0.1881 -0.04675 0">
        <inertial pos="0.0049166 0.00762615 -8.865e-05" quat="0.495027 0.482891 0.507341 0.514169" mass="0.68"
                  diaginertia="0.000734064 0.000468438 0.000398719"/>
        <joint name="RR_hip_joint" class="abduction"/>
        <geom quat="0 0 0 -1" type="mesh" class="visual" material="metal" mesh="hip"/>
        <geom size="0.046 0.02" pos="0 -0.08 0" quat="0.707107 0.707107 0 0" type="cylinder" class="collision"/>
        <geom size="0.035 0.01" pos="0 0.00015 0" quat="0.707107 0.707107 0 0" type="cylinder" contype="0"
              conaffinity="0" group="2" density="0" rgba="0 0.8 0 1"/>
        <geom size="0.035 0.01" pos="0 0.00015 0" quat="0.707107 0.707107 0 0" type="cylinder" rgba="0 0.8 0 1"/>
        <body name="RR_thigh" pos="0 -0.08 0">
          <inertial pos="-0.00304722 0.019315 -0.0305004" quat="0.65243 -0.0272313 0.0775126 0.753383" mass="1.009"
                    diaginertia="0.00478717 0.00460903 0.000709268"/>
          <joint name="RR_thigh_joint" class="back_hip"/>
          <geom type="mesh" class="visual" material="metal" mesh="thigh_mirror"/>
          <geom size="0.1065 0.01225 0.017" pos="0 0 -0.1065" quat="0.707107 0 0.707107 0" type="box"
                class="collision"/>
          <geom size="0.035 0.01" pos="0 0.03235 0" quat="0.707107 0.707107 0 0" type="cylinder" contype="0"
                conaffinity="0" group="2" density="0" rgba="0 0.8 0 1"/>
          <geom size="0.035 0.01" pos="0 0.03235 0" quat="0.707107 0.707107 0 0" type="cylinder" rgba="0 0.8 0 1"/>
          <body name="RR_calf" pos="0 0 -0.213">
            <inertial pos="0.00429862 0.000976676 -0.146197" quat="0.691246 0.00357467 0.00511118 0.722592"
                      mass="0.195862" diaginertia="0.00149767 0.00148468 3.58427e-05"/>
            <joint name="RR_calf_joint" class="knee"/>
            <geom type="mesh" class="visual" material="dark" mesh="calf"/>
            <geom size="0.1065 0.008 0.008" pos="0 0 -0.1065" quat="0.707107 0 0.707107 0" type="box"
                  class="collision"/>
            <geom size="0.01" pos="0 0 -0.213" contype="0" conaffinity="0" group="2" density="0"/>
            <geom size="0.02" pos="0 0 -0.213"/>
            <site name="RR_touch" pos="0 0 -0.213" size="0.027" material="transparent"/>
          </body>
        </body>
      </body>
    </body>
  </worldbody>

  <actuator>
    <motor class="abduction" name="FR_hip" joint="FR_hip_joint"/>
    <motor class="hip" name="FR_thigh" joint="FR_thigh_joint"/>
    <motor class="knee" name="FR_calf" joint="FR_calf_joint"/>
    <motor class="abduction" name="FL_hip" joint="FL_hip_joint"/>
    <motor class="hip" name="FL_thigh" joint="FL_thigh_joint"/>
    <motor class="knee" name="FL_calf" joint="FL_calf_joint"/>
    <motor class="abduction" name="RR_hip" joint="RR_hip_joint"/>
    <motor class="hip" name="RR_thigh" joint="RR_thigh_joint"/>
    <motor class="knee" name="RR_calf" joint="RR_calf_joint"/>
    <motor class="abduction" name="RL_hip" joint="RL_hip_joint"/>
    <motor class="hip" name="RL_thigh" joint="RL_thigh_joint"/>
    <motor class="knee" name="RL_calf" joint="RL_calf_joint"/>
  </actuator>

  <sensor>
    <jointpos name="FR_hip_pos" joint="FR_hip_joint"/>
    <jointpos name="FR_thigh_pos" joint="FR_thigh_joint"/>
    <jointpos name="FR_calf_pos" joint="FR_calf_joint"/>
    <jointpos name="FL_hip_pos" joint="FL_hip_joint"/>
    <jointpos name="FL_thigh_pos" joint="FL_thigh_joint"/>
    <jointpos name="FL_calf_pos" joint="FL_calf_joint"/>
    <jointpos name="RR_hip_pos" joint="RR_hip_joint"/>
    <jointpos name="RR_thigh_pos" joint="RR_thigh_joint"/>
    <jointpos name="RR_calf_pos" joint="RR_calf_joint"/>
    <jointpos name="RL_hip_pos" joint="RL_hip_joint"/>
    <jointpos name="RL_thigh_pos" joint="RL_thigh_joint"/>
    <jointpos name="RL_calf_pos" joint="RL_calf_joint"/>

    <jointvel name="FR_hip_vel" joint="FR_hip_joint"/>
    <jointvel name="FR_thigh_vel" joint="FR_thigh_joint"/>
    <jointvel name="FR_calf_vel" joint="FR_calf_joint"/>
    <jointvel name="FL_hip_vel" joint="FL_hip_joint"/>
    <jointvel name="FL_thigh_vel" joint="FL_thigh_joint"/>
    <jointvel name="FL_calf_vel" joint="FL_calf_joint"/>
    <jointvel name="RR_hip_vel" joint="RR_hip_joint"/>
    <jointvel name="RR_thigh_vel" joint="RR_thigh_joint"/>
    <jointvel name="RR_calf_vel" joint="RR_calf_joint"/>
    <jointvel name="RL_hip_vel" joint="RL_hip_joint"/>
    <jointvel name="RL_thigh_vel" joint="RL_thigh_joint"/>
    <jointvel name="RL_calf_vel" joint="RL_calf_joint"/>

    <jointactuatorfrc name="FR_hip_torque" joint="FR_hip_joint" noise="0.01"/>
    <jointactuatorfrc name="FR_thigh_torque" joint="FR_thigh_joint" noise="0.01"/>
    <jointactuatorfrc name="FR_calf_torque" joint="FR_calf_joint" noise="0.01"/>
    <jointactuatorfrc name="FL_hip_torque" joint="FL_hip_joint" noise="0.01"/>
    <jointactuatorfrc name="FL_thigh_torque" joint="FL_thigh_joint" noise="0.01"/>
    <jointactuatorfrc name="FL_calf_torque" joint="FL_calf_joint" noise="0.01"/>
    <jointactuatorfrc name="RR_hip_torque" joint="RR_hip_joint" noise="0.01"/>
    <jointactuatorfrc name="RR_thigh_torque" joint="RR_thigh_joint" noise="0.01"/>
    <jointactuatorfrc name="RR_calf_torque" joint="RR_calf_joint" noise="0.01"/>
    <jointactuatorfrc name="RL_hip_torque" joint="RL_hip_joint" noise="0.01"/>
    <jointactuatorfrc name="RL_thigh_torque" joint="RL_thigh_joint" noise="0.01"/>
    <jointactuatorfrc name="RL_calf_torque" joint="RL_calf_joint" noise="0.01"/>

    <framequat name="imu_quat" objtype="site" objname="imu"/>
    <gyro name="imu_gyro" site="imu"/>
    <accelerometer name="imu_acc" site="imu"/>

    <framepos name="frame_pos" objtype="site" objname="imu"/>
    <framelinvel name="frame_vel" objtype="site" objname="imu"/>

    <touch name="FR_touch" site="FR_touch"/>
    <touch name="FL_touch" site="FL_touch"/>
    <touch name="RR_touch" site="RR_touch"/>
    <touch name="RL_touch" site="RL_touch"/>
  </sensor>

  <keyframe>
    <key name="home" qpos="0 0 0.1 1 0 0 0 0.5 1.2 -2.7 -0.5 1.2 -2.7 0.5 1.2 -2.7 -0.5 1.2 -2.7"
         ctrl="0 0 0 0 0 0 0 0 0 0 0 0" />
  </keyframe>
</mujoco>
